Workbook

Sheet Cohortes Resumen
A1: MÉXICO — NRR DE COHORTES POR SEGMENTO DE TAMAÑO
A2: Cohorte del mes X = conglomerados de México con MRR > 0 en el período base terminado en X-12 (los creados después quedan fuera). NRR y GRR calculados 100% en MXN; USD sólo para segmentar por tamaño (TC del mes base). Fuga = MRR actual = 0. GRR = MRR retenido (MIN(actual; base)) / MRR base, sin expansión.
A4: NRR 2025-12 — Base mensual (base: período terminado en 2024-12)
A5: Segmento | B5: N cohorte | C5: Fuga (n) | D5: % Fuga | E5: GRR | F5: NRR (MXN)
A6: Menos de 100 USD | B6: =COUNTIFS('Cohorte Detalle 2025-12'!C2:C784,">0",'Cohorte Detalle 2025-12'!G2:G784,"Menos de 100 USD") -> 117 | C6: =COUNTIFS('Cohorte Detalle 2025-12'!C2:C784,">0",'Cohorte Detalle 2025-12'!D2:D784,"<=0",'Cohorte Detalle 2025-12'!G2:G784,"Menos de 100 USD") -> 36 | D6: =IFERROR(COUNTIFS('Cohorte Detalle 2025-12'!C2:C784,">0",'Cohorte Detalle 2025-12'!D2:D784,"<=0",'Cohorte Detalle 2025-12'!G2:G784,"Menos de 100 USD")/COUNTIFS('Cohorte Detalle 2025-12'!C2:C784,">0",'Cohorte Detalle 2025-12'!G2:G784,"Menos de 100 USD"),"") -> 0.30769231 | E6: =IFERROR(SUMIFS('Cohorte Detalle 2025-12'!H2:H784,'Cohorte Detalle 2025-12'!G2:G784,"Menos de 100 USD")/SUMIFS('Cohorte Detalle 2025-12'!C2:C784,'Cohorte Detalle 2025-12'!G2:G784,"Menos de 100 USD"),"") -> 0.68682881 | F6: =IFERROR(SUMIFS('Cohorte Detalle 2025-12'!D2:D784,'Cohorte Detalle 2025-12'!G2:G784,"Menos de 100 USD")/SUMIFS('Cohorte Detalle 2025-12'!C2:C784,'Cohorte Detalle 2025-12'!G2:G784,"Menos de 100 USD"),"") -> 0.96818448
A7: 100 a 500 USD | B7: =COUNTIFS('Cohorte Detalle 2025-12'!C2:C784,">0",'Cohorte Detalle 2025-12'!G2:G784,"100 a 500 USD") -> 139 | C7: =COUNTIFS('Cohorte Detalle 2025-12'!C2:C784,">0",'Cohorte Detalle 2025-12'!D2:D784,"<=0",'Cohorte Detalle 2025-12'!G2:G784,"100 a 500 USD") -> 26 | D7: =IFERROR(COUNTIFS('Cohorte Detalle 2025-12'!C2:C784,">0",'Cohorte Detalle 2025-12'!D2:D784,"<=0",'Cohorte Detalle 2025-12'!G2:G784,"100 a 500 USD")/COUNTIFS('Cohorte Detalle 2025-12'!C2:C784,">0",'Cohorte Detalle 2025-12'!G2:G784,"100 a 500 USD"),"") -> 0.18705036 | E7: =IFERROR(SUMIFS('Cohorte Detalle 2025-12'!H2:H784,'Cohorte Detalle 2025-12'!G2:G784,"100 a 500 USD")/SUMIFS('Cohorte Detalle 2025-12'!C2:C784,'Cohorte Detalle 2025-12'!G2:G784,"100 a 500 USD"),"") -> 0.73550933 | F7: =IFERROR(SUMIFS('Cohorte Detalle 2025-12'!D2:D784,'Cohorte Detalle 2025-12'!G2:G784,"100 a 500 USD")/SUMIFS('Cohorte Detalle 2025-12'!C2:C784,'Cohorte Detalle 2025-12'!G2:G784,"100 a 500 USD"),"") -> 0.92260453
A8: 500 a 2.000 USD | B8: =COUNTIFS('Cohorte Detalle 2025-12'!C2:C784,">0",'Cohorte Detalle 2025-12'!G2:G784,"500 a 2.000 USD") -> 47 | C8: =COUNTIFS('Cohorte Detalle 2025-12'!C2:C784,">0",'Cohorte Detalle 2025-12'!D2:D784,"<=0",'Cohorte Detalle 2025-12'!G2:G784,"500 a 2.000 USD") -> 5 | D8: =IFERROR(COUNTIFS('Cohorte Detalle 2025-12'!C2:C784,">0",'Cohorte Detalle 2025-12'!D2:D784,"<=0",'Cohorte Detalle 2025-12'!G2:G784,"500 a 2.000 USD")/COUNTIFS('Cohorte Detalle 2025-12'!C2:C784,">0",'Cohorte Detalle 2025-12'!G2:G784,"500 a 2.000 USD"),"") -> 0.10638298 | E8: =IFERROR(SUMIFS('Cohorte Detalle 2025-12'!H2:H784,'Cohorte Detalle 2025-12'!G2:G784,"500 a 2.000 USD")/SUMIFS('Cohorte Detalle 2025-12'!C2:C784,'Cohorte Detalle 2025-12'!G2:G784,"500 a 2.000 USD"),"") -> 0.73006248 | F8: =IFERROR(SUMIFS('Cohorte Detalle 2025-12'!D2:D784,'Cohorte Detalle 2025-12'!G2:G784,"500 a 2.000 USD")/SUMIFS('Cohorte Detalle 2025-12'!C2:C784,'Cohorte Detalle 2025-12'!G2:G784,"500 a 2.000 USD"),"") -> 0.92351683
A9: Más de 2.000 USD | B9: =COUNTIFS('Cohorte Detalle 2025-12'!C2:C784,">0",'Cohorte Detalle 2025-12'!G2:G784,"Más de 2.000 USD") -> 5 | C9: =COUNTIFS('Cohorte Detalle 2025-12'!C2:C784,">0",'Cohorte Detalle 2025-12'!D2:D784,"<=0",'Cohorte Detalle 2025-12'!G2:G784,"Más de 2.000 USD") -> 0 | D9: =IFERROR(COUNTIFS('Cohorte Detalle 2025-12'!C2:C784,">0",'Cohorte Detalle 2025-12'!D2:D784,"<=0",'Cohorte Detalle 2025-12'!G2:G784,"Más de 2.000 USD")/COUNTIFS('Cohorte Detalle 2025-12'!C2:C784,">0",'Cohorte Detalle 2025-12'!G2:G784,"Más de 2.000 USD"),"") -> 0 | E9: =IFERROR(SUMIFS('Cohorte Detalle 2025-12'!H2:H784,'Cohorte Detalle 2025-12'!G2:G784,"Más de 2.000 USD")/SUMIFS('Cohorte Detalle 2025-12'!C2:C784,'Cohorte Detalle 2025-12'!G2:G784,"Más de 2.000 USD"),"") -> 0.65592353 | F9: =IFERROR(SUMIFS('Cohorte Detalle 2025-12'!D2:D784,'Cohorte Detalle 2025-12'!G2:G784,"Más de 2.000 USD")/SUMIFS('Cohorte Detalle 2025-12'!C2:C784,'Cohorte Detalle 2025-12'!G2:G784,"Más de 2.000 USD"),"") -> 0.71017154
A10: Total México | B10: =COUNTIFS('Cohorte Detalle 2025-12'!C2:C784,">0") -> 308 | C10: =COUNTIFS('Cohorte Detalle 2025-12'!C2:C784,">0",'Cohorte Detalle 2025-12'!D2:D784,"<=0") -> 67 | D10: =IFERROR(COUNTIFS('Cohorte Detalle 2025-12'!C2:C784,">0",'Cohorte Detalle 2025-12'!D2:D784,"<=0")/COUNTIFS('Cohorte Detalle 2025-12'!C2:C784,">0"),"") -> 0.21753247 | E10: =IFERROR(SUM('Cohorte Detalle 2025-12'!H2:H784)/SUM('Cohorte Detalle 2025-12'!C2:C784),"") -> 0.71837245 | F10: =IFERROR(SUM('Cohorte Detalle 2025-12'!D2:D784)/SUM('Cohorte Detalle 2025-12'!C2:C784),"") -> 0.89396349
A13: NRR 2025-12 — Base trimestral (base: período terminado en 2024-12)
A14: Segmento | B14: N cohorte | C14: Fuga (n) | D14: % Fuga | E14: GRR | F14: NRR (MXN)
A15: Menos de 100 USD | B15: =COUNTIFS('Cohorte Detalle 2025-12'!I2:I784,">0",'Cohorte Detalle 2025-12'!N2:N784,"Menos de 100 USD") -> 132 | C15: =COUNTIFS('Cohorte Detalle 2025-12'!I2:I784,">0",'Cohorte Detalle 2025-12'!J2:J784,"<=0",'Cohorte Detalle 2025-12'!N2:N784,"Menos de 100 USD") -> 46 | D15: =IFERROR(COUNTIFS('Cohorte Detalle 2025-12'!I2:I784,">0",'Cohorte Detalle 2025-12'!J2:J784,"<=0",'Cohorte Detalle 2025-12'!N2:N784,"Menos de 100 USD")/COUNTIFS('Cohorte Detalle 2025-12'!I2:I784,">0",'Cohorte Detalle 2025-12'!N2:N784,"Menos de 100 USD"),"") -> 0.34848485 | E15: =IFERROR(SUMIFS('Cohorte Detalle 2025-12'!O2:O784,'Cohorte Detalle 2025-12'!N2:N784,"Menos de 100 USD")/SUMIFS('Cohorte Detalle 2025-12'!I2:I784,'Cohorte Detalle 2025-12'!N2:N784,"Menos de 100 USD"),"") -> 0.68594946 | F15: =IFERROR(SUMIFS('Cohorte Detalle 2025-12'!J2:J784,'Cohorte Detalle 2025-12'!N2:N784,"Menos de 100 USD")/SUMIFS('Cohorte Detalle 2025-12'!I2:I784,'Cohorte Detalle 2025-12'!N2:N784,"Menos de 100 USD"),"") -> 1.1685948
A16: 100 a 500 USD | B16: =COUNTIFS('Cohorte Detalle 2025-12'!I2:I784,">0",'Cohorte Detalle 2025-12'!N2:N784,"100 a 500 USD") -> 148 | C16: =COUNTIFS('Cohorte Detalle 2025-12'!I2:I784,">0",'Cohorte Detalle 2025-12'!J2:J784,"<=0",'Cohorte Detalle 2025-12'!N2:N784,"100 a 500 USD") -> 30 | D16: =IFERROR(COUNTIFS('Cohorte Detalle 2025-12'!I2:I784,">0",'Cohorte Detalle 2025-12'!J2:J784,"<=0",'Cohorte Detalle 2025-12'!N2:N784,"100 a 500 USD")/COUNTIFS('Cohorte Detalle 2025-12'!I2:I784,">0",'Cohorte Detalle 2025-12'!N2:N784,"100 a 500 USD"),"") -> 0.2027027 | E16: =IFERROR(SUMIFS('Cohorte Detalle 2025-12'!O2:O784,'Cohorte Detalle 2025-12'!N2:N784,"100 a 500 USD")/SUMIFS('Cohorte Detalle 2025-12'!I2:I784,'Cohorte Detalle 2025-12'!N2:N784,"100 a 500 USD"),"") -> 0.72684651 | F16: =IFERROR(SUMIFS('Cohorte Detalle 2025-12'!J2:J784,'Cohorte Detalle 2025-12'!N2:N784,"100 a 500 USD")/SUMIFS('Cohorte Detalle 2025-12'!I2:I784,'Cohorte Detalle 2025-12'!N2:N784,"100 a 500 USD"),"") -> 0.92882429
A17: 500 a 2.000 USD | B17: =COUNTIFS('Cohorte Detalle 2025-12'!I2:I784,">0",'Cohorte Detalle 2025-12'!N2:N784,"500 a 2.000 USD") -> 51 | C17: =COUNTIFS('Cohorte Detalle 2025-12'!I2:I784,">0",'Cohorte Detalle 2025-12'!J2:J784,"<=0",'Cohorte Detalle 2025-12'!N2:N784,"500 a 2.000 USD") -> 6 | D17: =IFERROR(COUNTIFS('Cohorte Detalle 2025-12'!I2:I784,">0",'Cohorte Detalle 2025-12'!J2:J784,"<=0",'Cohorte Detalle 2025-12'!N2:N784,"500 a 2.000 USD")/COUNTIFS('Cohorte Detalle 2025-12'!I2:I784,">0",'Cohorte Detalle 2025-12'!N2:N784,"500 a 2.000 USD"),"") -> 0.11764706 | E17: =IFERROR(SUMIFS('Cohorte Detalle 2025-12'!O2:O784,'Cohorte Detalle 2025-12'!N2:N784,"500 a 2.000 USD")/SUMIFS('Cohorte Detalle 2025-12'!I2:I784,'Cohorte Detalle 2025-12'!N2:N784,"500 a 2.000 USD"),"") -> 0.72974357 | F17: =IFERROR(SUMIFS('Cohorte Detalle 2025-12'!J2:J784,'Cohorte Detalle 2025-12'!N2:N784,"500 a 2.000 USD")/SUMIFS('Cohorte Detalle 2025-12'!I2:I784,'Cohorte Detalle 2025-12'!N2:N784,"500 a 2.000 USD"),"") -> 0.9693194
A18: Más de 2.000 USD | B18: =COUNTIFS('Cohorte Detalle 2025-12'!I2:I784,">0",'Cohorte Detalle 2025-12'!N2:N784,"Más de 2.000 USD") -> 6 | C18: =COUNTIFS('Cohorte Detalle 2025-12'!I2:I784,">0",'Cohorte Detalle 2025-12'!J2:J784,"<=0",'Cohorte Detalle 2025-12'!N2:N784,"Más de 2.000 USD") -> 1 | D18: =IFERROR(COUNTIFS('Cohorte Detalle 2025-12'!I2:I784,">0",'Cohorte Detalle 2025-12'!J2:J784,"<=0",'Cohorte Detalle 2025-12'!N2:N784,"Más de 2.000 USD")/COUNTIFS('Cohorte Detalle 2025-12'!I2:I784,">0",'Cohorte Detalle 2025-12'!N2:N784,"Más de 2.000 USD"),"") -> 0.16666667 | E18: =IFERROR(SUMIFS('Cohorte Detalle 2025-12'!O2:O784,'Cohorte Detalle 2025-12'!N2:N784,"Más de 2.000 USD")/SUMIFS('Cohorte Detalle 2025-12'!I2:I784,'Cohorte Detalle 2025-12'!N2:N784,"Más de 2.000 USD"),"") -> 0.66473796 | F18: =IFERROR(SUMIFS('Cohorte Detalle 2025-12'!J2:J784,'Cohorte Detalle 2025-12'!N2:N784,"Más de 2.000 USD")/SUMIFS('Cohorte Detalle 2025-12'!I2:I784,'Cohorte Detalle 2025-12'!N2:N784,"Más de 2.000 USD"),"") -> 0.8595139
A19: Total México | B19: =COUNTIFS('Cohorte Detalle 2025-12'!I2:I784,">0") -> 337 | C19: =COUNTIFS('Cohorte Detalle 2025-12'!I2:I784,">0",'Cohorte Detalle 2025-12'!J2:J784,"<=0") -> 83 | D19: =IFERROR(COUNTIFS('Cohorte Detalle 2025-12'!I2:I784,">0",'Cohorte Detalle 2025-12'!J2:J784,"<=0")/COUNTIFS('Cohorte Detalle 2025-12'!I2:I784,">0"),"") -> 0.2462908 | E19: =IFERROR(SUM('Cohorte Detalle 2025-12'!O2:O784)/SUM('Cohorte Detalle 2025-12'!I2:I784),"") -> 0.71765133 | F19: =IFERROR(SUM('Cohorte Detalle 2025-12'!J2:J784)/SUM('Cohorte Detalle 2025-12'!I2:I784),"") -> 0.95283986
A22: NRR 2025-12 — Base anual (base: período terminado en 2024-12)
A23: Segmento | B23: N cohorte | C23: Fuga (n) | D23: % Fuga | E23: GRR | F23: NRR (MXN)
A24: Menos de 100 USD | B24: =COUNTIFS('Cohorte Detalle 2025-12'!S2:S784,">0",'Cohorte Detalle 2025-12'!W2:W784,"Menos de 100 USD") -> 166 | C24: =COUNTIFS('Cohorte Detalle 2025-12'!S2:S784,">0",'Cohorte Detalle 2025-12'!T2:T784,"<=0",'Cohorte Detalle 2025-12'!W2:W784,"Menos de 100 USD") -> 44 | D24: =IFERROR(COUNTIFS('Cohorte Detalle 2025-12'!S2:S784,">0",'Cohorte Detalle 2025-12'!T2:T784,"<=0",'Cohorte Detalle 2025-12'!W2:W784,"Menos de 100 USD")/COUNTIFS('Cohorte Detalle 2025-12'!S2:S784,">0",'Cohorte Detalle 2025-12'!W2:W784,"Menos de 100 USD"),"") -> 0.26506024 | E24: =IFERROR(SUMIFS('Cohorte Detalle 2025-12'!X2:X784,'Cohorte Detalle 2025-12'!W2:W784,"Menos de 100 USD")/SUMIFS('Cohorte Detalle 2025-12'!S2:S784,'Cohorte Detalle 2025-12'!W2:W784,"Menos de 100 USD"),"") -> 0.60367612 | F24: =IFERROR(SUMIFS('Cohorte Detalle 2025-12'!T2:T784,'Cohorte Detalle 2025-12'!W2:W784,"Menos de 100 USD")/SUMIFS('Cohorte Detalle 2025-12'!S2:S784,'Cohorte Detalle 2025-12'!W2:W784,"Menos de 100 USD"),"") -> 0.85517162
A25: 100 a 500 USD | B25: =COUNTIFS('Cohorte Detalle 2025-12'!S2:S784,">0",'Cohorte Detalle 2025-12'!W2:W784,"100 a 500 USD") -> 178 | C25: =COUNTIFS('Cohorte Detalle 2025-12'!S2:S784,">0",'Cohorte Detalle 2025-12'!T2:T784,"<=0",'Cohorte Detalle 2025-12'!W2:W784,"100 a 500 USD") -> 30 | D25: =IFERROR(COUNTIFS('Cohorte Detalle 2025-12'!S2:S784,">0",'Cohorte Detalle 2025-12'!T2:T784,"<=0",'Cohorte Detalle 2025-12'!W2:W784,"100 a 500 USD")/COUNTIFS('Cohorte Detalle 2025-12'!S2:S784,">0",'Cohorte Detalle 2025-12'!W2:W784,"100 a 500 USD"),"") -> 0.16853933 | E25: =IFERROR(SUMIFS('Cohorte Detalle 2025-12'!X2:X784,'Cohorte Detalle 2025-12'!W2:W784,"100 a 500 USD")/SUMIFS('Cohorte Detalle 2025-12'!S2:S784,'Cohorte Detalle 2025-12'!W2:W784,"100 a 500 USD"),"") -> 0.693488 | F25: =IFERROR(SUMIFS('Cohorte Detalle 2025-12'!T2:T784,'Cohorte Detalle 2025-12'!W2:W784,"100 a 500 USD")/SUMIFS('Cohorte Detalle 2025-12'!S2:S784,'Cohorte Detalle 2025-12'!W2:W784,"100 a 500 USD"),"") -> 0.84486512
A26: 500 a 2.000 USD | B26: =COUNTIFS('Cohorte Detalle 2025-12'!S2:S784,">0",'Cohorte Detalle 2025-12'!W2:W784,"500 a 2.000 USD") -> 56 | C26: =COUNTIFS('Cohorte Detalle 2025-12'!S2:S784,">0",'Cohorte Detalle 2025-12'!T2:T784,"<=0",'Cohorte Detalle 2025-12'!W2:W784,"500 a 2.000 USD") -> 11 | D26: =IFERROR(COUNTIFS('Cohorte Detalle 2025-12'!S2:S784,">0",'Cohorte Detalle 2025-12'!T2:T784,"<=0",'Cohorte Detalle 2025-12'!W2:W784,"500 a 2.000 USD")/COUNTIFS('Cohorte Detalle 2025-12'!S2:S784,">0",'Cohorte Detalle 2025-12'!W2:W784,"500 a 2.000 USD"),"") -> 0.19642857 | E26: =IFERROR(SUMIFS('Cohorte Detalle 2025-12'!X2:X784,'Cohorte Detalle 2025-12'!W2:W784,"500 a 2.000 USD")/SUMIFS('Cohorte Detalle 2025-12'!S2:S784,'Cohorte Detalle 2025-12'!W2:W784,"500 a 2.000 USD"),"") -> 0.6767396 | F26: =IFERROR(SUMIFS('Cohorte Detalle 2025-12'!T2:T784,'Cohorte Detalle 2025-12'!W2:W784,"500 a 2.000 USD")/SUMIFS('Cohorte Detalle 2025-12'!S2:S784,'Cohorte Detalle 2025-12'!W2:W784,"500 a 2.000 USD"),"") -> 0.7414603
A27: Más de 2.000 USD | B27: =COUNTIFS('Cohorte Detalle 2025-12'!S2:S784,">0",'Cohorte Detalle 2025-12'!W2:W784,"Más de 2.000 USD") -> 5 | C27: =COUNTIFS('Cohorte Detalle 2025-12'!S2:S784,">0",'Cohorte Detalle 2025-12'!T2:T784,"<=0",'Cohorte Detalle 2025-12'!W2:W784,"Más de 2.000 USD") -> 1 | D27: =IFERROR(COUNTIFS('Cohorte Detalle 2025-12'!S2:S784,">0",'Cohorte Detalle 2025-12'!T2:T784,"<=0",'Cohorte Detalle 2025-12'!W2:W784,"Más de 2.000 USD")/COUNTIFS('Cohorte Detalle 2025-12'!S2:S784,">0",'Cohorte Detalle 2025-12'!W2:W784,"Más de 2.000 USD"),"") -> 0.2 | E27: =IFERROR(SUMIFS('Cohorte Detalle 2025-12'!X2:X784,'Cohorte Detalle 2025-12'!W2:W784,"Más de 2.000 USD")/SUMIFS('Cohorte Detalle 2025-12'!S2:S784,'Cohorte Detalle 2025-12'!W2:W784,"Más de 2.000 USD"),"") -> 0.6081435 | F27: =IFERROR(SUMIFS('Cohorte Detalle 2025-12'!T2:T784,'Cohorte Detalle 2025-12'!W2:W784,"Más de 2.000 USD")/SUMIFS('Cohorte Detalle 2025-12'!S2:S784,'Cohorte Detalle 2025-12'!W2:W784,"Más de 2.000 USD"),"") -> 0.7232548
A28: Total México | B28: =COUNTIFS('Cohorte Detalle 2025-12'!S2:S784,">0") -> 405 | C28: =COUNTIFS('Cohorte Detalle 2025-12'!S2:S784,">0",'Cohorte Detalle 2025-12'!T2:T784,"<=0") -> 86 | D28: =IFERROR(COUNTIFS('Cohorte Detalle 2025-12'!S2:S784,">0",'Cohorte Detalle 2025-12'!T2:T784,"<=0")/COUNTIFS('Cohorte Detalle 2025-12'!S2:S784,">0"),"") -> 0.21234568 | E28: =IFERROR(SUM('Cohorte Detalle 2025-12'!X2:X784)/SUM('Cohorte Detalle 2025-12'!S2:S784),"") -> 0.67077419 | F28: =IFERROR(SUM('Cohorte Detalle 2025-12'!T2:T784)/SUM('Cohorte Detalle 2025-12'!S2:S784),"") -> 0.7850468
A31: NRR 2026-06 — Base mensual (base: período terminado en 2025-06)
A32: Segmento | B32: N cohorte | C32: Fuga (n) | D32: % Fuga | E32: GRR | F32: NRR (MXN)
A33: Menos de 100 USD | B33: =COUNTIFS('Cohorte Detalle 2026-06'!C2:C784,">0",'Cohorte Detalle 2026-06'!G2:G784,"Menos de 100 USD") -> 125 | C33: =COUNTIFS('Cohorte Detalle 2026-06'!C2:C784,">0",'Cohorte Detalle 2026-06'!D2:D784,"<=0",'Cohorte Detalle 2026-06'!G2:G784,"Menos de 100 USD") -> 46 | D33: =IFERROR(COUNTIFS('Cohorte Detalle 2026-06'!C2:C784,">0",'Cohorte Detalle 2026-06'!D2:D784,"<=0",'Cohorte Detalle 2026-06'!G2:G784,"Menos de 100 USD")/COUNTIFS('Cohorte Detalle 2026-06'!C2:C784,">0",'Cohorte Detalle 2026-06'!G2:G784,"Menos de 100 USD"),"") -> 0.368 | E33: =IFERROR(SUMIFS('Cohorte Detalle 2026-06'!H2:H784,'Cohorte Detalle 2026-06'!G2:G784,"Menos de 100 USD")/SUMIFS('Cohorte Detalle 2026-06'!C2:C784,'Cohorte Detalle 2026-06'!G2:G784,"Menos de 100 USD"),"") -> 0.65358351 | F33: =IFERROR(SUMIFS('Cohorte Detalle 2026-06'!D2:D784,'Cohorte Detalle 2026-06'!G2:G784,"Menos de 100 USD")/SUMIFS('Cohorte Detalle 2026-06'!C2:C784,'Cohorte Detalle 2026-06'!G2:G784,"Menos de 100 USD"),"") -> 0.91827528
A34: 100 a 500 USD | B34: =COUNTIFS('Cohorte Detalle 2026-06'!C2:C784,">0",'Cohorte Detalle 2026-06'!G2:G784,"100 a 500 USD") -> 166 | C34: =COUNTIFS('Cohorte Detalle 2026-06'!C2:C784,">0",'Cohorte Detalle 2026-06'!D2:D784,"<=0",'Cohorte Detalle 2026-06'!G2:G784,"100 a 500 USD") -> 31 | D34: =IFERROR(COUNTIFS('Cohorte Detalle 2026-06'!C2:C784,">0",'Cohorte Detalle 2026-06'!D2:D784,"<=0",'Cohorte Detalle 2026-06'!G2:G784,"100 a 500 USD")/COUNTIFS('Cohorte Detalle 2026-06'!C2:C784,">0",'Cohorte Detalle 2026-06'!G2:G784,"100 a 500 USD"),"") -> 0.18674699 | E34: =IFERROR(SUMIFS('Cohorte Detalle 2026-06'!H2:H784,'Cohorte Detalle 2026-06'!G2:G784,"100 a 500 USD")/SUMIFS('Cohorte Detalle 2026-06'!C2:C784,'Cohorte Detalle 2026-06'!G2:G784,"100 a 500 USD"),"") -> 0.71604021 | F34: =IFERROR(SUMIFS('Cohorte Detalle 2026-06'!D2:D784,'Cohorte Detalle 2026-06'!G2:G784,"100 a 500 USD")/SUMIFS('Cohorte Detalle 2026-06'!C2:C784,'Cohorte Detalle 2026-06'!G2:G784,"100 a 500 USD"),"") -> 0.93279317
A35: 500 a 2.000 USD | B35: =COUNTIFS('Cohorte Detalle 2026-06'!C2:C784,">0",'Cohorte Detalle 2026-06'!G2:G784,"500 a 2.000 USD") -> 51 | C35: =COUNTIFS('Cohorte Detalle 2026-06'!C2:C784,">0",'Cohorte Detalle 2026-06'!D2:D784,"<=0",'Cohorte Detalle 2026-06'!G2:G784,"500 a 2.000 USD") -> 9 | D35: =IFERROR(COUNTIFS('Cohorte Detalle 2026-06'!C2:C784,">0",'Cohorte Detalle 2026-06'!D2:D784,"<=0",'Cohorte Detalle 2026-06'!G2:G784,"500 a 2.000 USD")/COUNTIFS('Cohorte Detalle 2026-06'!C2:C784,">0",'Cohorte Detalle 2026-06'!G2:G784,"500 a 2.000 USD"),"") -> 0.17647059 | E35: =IFERROR(SUMIFS('Cohorte Detalle 2026-06'!H2:H784,'Cohorte Detalle 2026-06'!G2:G784,"500 a 2.000 USD")/SUMIFS('Cohorte Detalle 2026-06'!C2:C784,'Cohorte Detalle 2026-06'!G2:G784,"500 a 2.000 USD"),"") -> 0.75998045 | F35: =IFERROR(SUMIFS('Cohorte Detalle 2026-06'!D2:D784,'Cohorte Detalle 2026-06'!G2:G784,"500 a 2.000 USD")/SUMIFS('Cohorte Detalle 2026-06'!C2:C784,'Cohorte Detalle 2026-06'!G2:G784,"500 a 2.000 USD"),"") -> 0.93446329
A36: Más de 2.000 USD | B36: =COUNTIFS('Cohorte Detalle 2026-06'!C2:C784,">0",'Cohorte Detalle 2026-06'!G2:G784,"Más de 2.000 USD") -> 5 | C36: =COUNTIFS('Cohorte Detalle 2026-06'!C2:C784,">0",'Cohorte Detalle 2026-06'!D2:D784,"<=0",'Cohorte Detalle 2026-06'!G2:G784,"Más de 2.000 USD") -> 0 | D36: =IFERROR(COUNTIFS('Cohorte Detalle 2026-06'!C2:C784,">0",'Cohorte Detalle 2026-06'!D2:D784,"<=0",'Cohorte Detalle 2026-06'!G2:G784,"Más de 2.000 USD")/COUNTIFS('Cohorte Detalle 2026-06'!C2:C784,">0",'Cohorte Detalle 2026-06'!G2:G784,"Más de 2.000 USD"),"") -> 0 | E36: =IFERROR(SUMIFS('Cohorte Detalle 2026-06'!H2:H784,'Cohorte Detalle 2026-06'!G2:G784,"Más de 2.000 USD")/SUMIFS('Cohorte Detalle 2026-06'!C2:C784,'Cohorte Detalle 2026-06'!G2:G784,"Más de 2.000 USD"),"") -> 0.99479938 | F36: =IFERROR(SUMIFS('Cohorte Detalle 2026-06'!D2:D784,'Cohorte Detalle 2026-06'!G2:G784,"Más de 2.000 USD")/SUMIFS('Cohorte Detalle 2026-06'!C2:C784,'Cohorte Detalle 2026-06'!G2:G784,"Más de 2.000 USD"),"") -> 1.281245
A37: Total México | B37: =COUNTIFS('Cohorte Detalle 2026-06'!C2:C784,">0") -> 347 | C37: =COUNTIFS('Cohorte Detalle 2026-06'!C2:C784,">0",'Cohorte Detalle 2026-06'!D2:D784,"<=0") -> 86 | D37: =IFERROR(COUNTIFS('Cohorte Detalle 2026-06'!C2:C784,">0",'Cohorte Detalle 2026-06'!D2:D784,"<=0")/COUNTIFS('Cohorte Detalle 2026-06'!C2:C784,">0"),"") -> 0.24783862 | E37: =IFERROR(SUM('Cohorte Detalle 2026-06'!H2:H784)/SUM('Cohorte Detalle 2026-06'!C2:C784),"") -> 0.76716609 | F37: =IFERROR(SUM('Cohorte Detalle 2026-06'!D2:D784)/SUM('Cohorte Detalle 2026-06'!C2:C784),"") -> 0.97602044
A40: NRR 2026-06 — Base trimestral (base: período terminado en 2025-06)
A41: Segmento | B41: N cohorte | C41: Fuga (n) | D41: % Fuga | E41: GRR | F41: NRR (MXN)
A42: Menos de 100 USD | B42: =COUNTIFS('Cohorte Detalle 2026-06'!I2:I784,">0",'Cohorte Detalle 2026-06'!N2:N784,"Menos de 100 USD") -> 131 | C42: =COUNTIFS('Cohorte Detalle 2026-06'!I2:I784,">0",'Cohorte Detalle 2026-06'!J2:J784,"<=0",'Cohorte Detalle 2026-06'!N2:N784,"Menos de 100 USD") -> 49 | D42: =IFERROR(COUNTIFS('Cohorte Detalle 2026-06'!I2:I784,">0",'Cohorte Detalle 2026-06'!J2:J784,"<=0",'Cohorte Detalle 2026-06'!N2:N784,"Menos de 100 USD")/COUNTIFS('Cohorte Detalle 2026-06'!I2:I784,">0",'Cohorte Detalle 2026-06'!N2:N784,"Menos de 100 USD"),"") -> 0.3740458 | E42: =IFERROR(SUMIFS('Cohorte Detalle 2026-06'!O2:O784,'Cohorte Detalle 2026-06'!N2:N784,"Menos de 100 USD")/SUMIFS('Cohorte Detalle 2026-06'!I2:I784,'Cohorte Detalle 2026-06'!N2:N784,"Menos de 100 USD"),"") -> 0.63372266 | F42: =IFERROR(SUMIFS('Cohorte Detalle 2026-06'!J2:J784,'Cohorte Detalle 2026-06'!N2:N784,"Menos de 100 USD")/SUMIFS('Cohorte Detalle 2026-06'!I2:I784,'Cohorte Detalle 2026-06'!N2:N784,"Menos de 100 USD"),"") -> 0.96363782
A43: 100 a 500 USD | B43: =COUNTIFS('Cohorte Detalle 2026-06'!I2:I784,">0",'Cohorte Detalle 2026-06'!N2:N784,"100 a 500 USD") -> 176 | C43: =COUNTIFS('Cohorte Detalle 2026-06'!I2:I784,">0",'Cohorte Detalle 2026-06'!J2:J784,"<=0",'Cohorte Detalle 2026-06'!N2:N784,"100 a 500 USD") -> 35 | D43: =IFERROR(COUNTIFS('Cohorte Detalle 2026-06'!I2:I784,">0",'Cohorte Detalle 2026-06'!J2:J784,"<=0",'Cohorte Detalle 2026-06'!N2:N784,"100 a 500 USD")/COUNTIFS('Cohorte Detalle 2026-06'!I2:I784,">0",'Cohorte Detalle 2026-06'!N2:N784,"100 a 500 USD"),"") -> 0.19886364 | E43: =IFERROR(SUMIFS('Cohorte Detalle 2026-06'!O2:O784,'Cohorte Detalle 2026-06'!N2:N784,"100 a 500 USD")/SUMIFS('Cohorte Detalle 2026-06'!I2:I784,'Cohorte Detalle 2026-06'!N2:N784,"100 a 500 USD"),"") -> 0.69875863 | F43: =IFERROR(SUMIFS('Cohorte Detalle 2026-06'!J2:J784,'Cohorte Detalle 2026-06'!N2:N784,"100 a 500 USD")/SUMIFS('Cohorte Detalle 2026-06'!I2:I784,'Cohorte Detalle 2026-06'!N2:N784,"100 a 500 USD"),"") -> 0.94274939
A44: 500 a 2.000 USD | B44: =COUNTIFS('Cohorte Detalle 2026-06'!I2:I784,">0",'Cohorte Detalle 2026-06'!N2:N784,"500 a 2.000 USD") -> 54 | C44: =COUNTIFS('Cohorte Detalle 2026-06'!I2:I784,">0",'Cohorte Detalle 2026-06'!J2:J784,"<=0",'Cohorte Detalle 2026-06'!N2:N784,"500 a 2.000 USD") -> 7 | D44: =IFERROR(COUNTIFS('Cohorte Detalle 2026-06'!I2:I784,">0",'Cohorte Detalle 2026-06'!J2:J784,"<=0",'Cohorte Detalle 2026-06'!N2:N784,"500 a 2.000 USD")/COUNTIFS('Cohorte Detalle 2026-06'!I2:I784,">0",'Cohorte Detalle 2026-06'!N2:N784,"500 a 2.000 USD"),"") -> 0.12962963 | E44: =IFERROR(SUMIFS('Cohorte Detalle 2026-06'!O2:O784,'Cohorte Detalle 2026-06'!N2:N784,"500 a 2.000 USD")/SUMIFS('Cohorte Detalle 2026-06'!I2:I784,'Cohorte Detalle 2026-06'!N2:N784,"500 a 2.000 USD"),"") -> 0.78983701 | F44: =IFERROR(SUMIFS('Cohorte Detalle 2026-06'!J2:J784,'Cohorte Detalle 2026-06'!N2:N784,"500 a 2.000 USD")/SUMIFS('Cohorte Detalle 2026-06'!I2:I784,'Cohorte Detalle 2026-06'!N2:N784,"500 a 2.000 USD"),"") -> 0.9808546
A45: Más de 2.000 USD | B45: =COUNTIFS('Cohorte Detalle 2026-06'!I2:I784,">0",'Cohorte Detalle 2026-06'!N2:N784,"Más de 2.000 USD") -> 5 | C45: =COUNTIFS('Cohorte Detalle 2026-06'!I2:I784,">0",'Cohorte Detalle 2026-06'!J2:J784,"<=0",'Cohorte Detalle 2026-06'!N2:N784,"Más de 2.000 USD") -> 0 | D45: =IFERROR(COUNTIFS('Cohorte Detalle 2026-06'!I2:I784,">0",'Cohorte Detalle 2026-06'!J2:J784,"<=0",'Cohorte Detalle 2026-06'!N2:N784,"Más de 2.000 USD")/COUNTIFS('Cohorte Detalle 2026-06'!I2:I784,">0",'Cohorte Detalle 2026-06'!N2:N784,"Más de 2.000 USD"),"") -> 0 | E45: =IFERROR(SUMIFS('Cohorte Detalle 2026-06'!O2:O784,'Cohorte Detalle 2026-06'!N2:N784,"Más de 2.000 USD")/SUMIFS('Cohorte Detalle 2026-06'!I2:I784,'Cohorte Detalle 2026-06'!N2:N784,"Más de 2.000 USD"),"") -> 0.99686493 | F45: =IFERROR(SUMIFS('Cohorte Detalle 2026-06'!J2:J784,'Cohorte Detalle 2026-06'!N2:N784,"Más de 2.000 USD")/SUMIFS('Cohorte Detalle 2026-06'!I2:I784,'Cohorte Detalle 2026-06'!N2:N784,"Más de 2.000 USD"),"") -> 1.337127
A46: Total México | B46: =COUNTIFS('Cohorte Detalle 2026-06'!I2:I784,">0") -> 366 | C46: =COUNTIFS('Cohorte Detalle 2026-06'!I2:I784,">0",'Cohorte Detalle 2026-06'!J2:J784,"<=0") -> 91 | D46: =IFERROR(COUNTIFS('Cohorte Detalle 2026-06'!I2:I784,">0",'Cohorte Detalle 2026-06'!J2:J784,"<=0")/COUNTIFS('Cohorte Detalle 2026-06'!I2:I784,">0"),"") -> 0.24863388 | E46: =IFERROR(SUM('Cohorte Detalle 2026-06'!O2:O784)/SUM('Cohorte Detalle 2026-06'!I2:I784),"") -> 0.77271752 | F46: =IFERROR(SUM('Cohorte Detalle 2026-06'!J2:J784)/SUM('Cohorte Detalle 2026-06'!I2:I784),"") -> 1.008578
A49: NRR 2026-06 — Base anual (base: período terminado en 2025-06)
A50: Segmento | B50: N cohorte | C50: Fuga (n) | D50: % Fuga | E50: GRR | F50: NRR (MXN)
A51: Menos de 100 USD | B51: =COUNTIFS('Cohorte Detalle 2026-06'!S2:S784,">0",'Cohorte Detalle 2026-06'!W2:W784,"Menos de 100 USD") -> 167 | C51: =COUNTIFS('Cohorte Detalle 2026-06'!S2:S784,">0",'Cohorte Detalle 2026-06'!T2:T784,"<=0",'Cohorte Detalle 2026-06'!W2:W784,"Menos de 100 USD") -> 55 | D51: =IFERROR(COUNTIFS('Cohorte Detalle 2026-06'!S2:S784,">0",'Cohorte Detalle 2026-06'!T2:T784,"<=0",'Cohorte Detalle 2026-06'!W2:W784,"Menos de 100 USD")/COUNTIFS('Cohorte Detalle 2026-06'!S2:S784,">0",'Cohorte Detalle 2026-06'!W2:W784,"Menos de 100 USD"),"") -> 0.32934132 | E51: =IFERROR(SUMIFS('Cohorte Detalle 2026-06'!X2:X784,'Cohorte Detalle 2026-06'!W2:W784,"Menos de 100 USD")/SUMIFS('Cohorte Detalle 2026-06'!S2:S784,'Cohorte Detalle 2026-06'!W2:W784,"Menos de 100 USD"),"") -> 0.56436582 | F51: =IFERROR(SUMIFS('Cohorte Detalle 2026-06'!T2:T784,'Cohorte Detalle 2026-06'!W2:W784,"Menos de 100 USD")/SUMIFS('Cohorte Detalle 2026-06'!S2:S784,'Cohorte Detalle 2026-06'!W2:W784,"Menos de 100 USD"),"") -> 0.71947346
...

Sheet MRR Conglomerado
A1: Conglomerado | B1: N° RUTs | C1: Filas en MRR_a_junio_26 (Moneda Loca v2) | D1: 2023-01 | E1: 2023-02 | F1: 2023-03 | G1: 2023-04 | H1: 2023-05 | I1: 2023-06 | J1: 2023-07 | K1: 2023-08 | L1: 2023-09 | M1: 2023-10 | N1: 2023-11 | O1: 2023-12 | P1: 2024-01 | Q1: 2024-02 | R1: 2024-03 | S1: 2024-04 | T1: 2024-05 | U1: 2024-06 | V1: 2024-07 | W1: 2024-08 | X1: 2024-09 | Y1: 2024-10 | Z1: 2024-11 | AA1: 2024-12 | AB1: 2025-01 | AC1: 2025-02 | AD1: 2025-03 | AE1: 2025-04 | AF1: 2025-05 | AG1: 2025-06 | AH1: 2025-07 | AI1: 2025-08 | AJ1: 2025-09 | AK1: 2025-10 | AL1: 2025-11 | AM1: 2025-12 | AN1: 2026-01 | AO1: 2026-02 | AP1: 2026-03 | AQ1: 2026-04 | AR1: 2026-05 | AS1: 2026-06
A2: 180719670 | B2: 1 | C2: 10780 | D2: 0 | E2: 0 | F2: 0 | G2: 0 | H2: 0 | I2: 0 | J2: 0 | K2: 0 | L2: 0 | M2: 0 | N2: 0 | O2: 0 | P2: 0 | Q2: 0 | R2: 0 | S2: 0 | T2: 0 | U2: 0 | V2: 0 | W2: 0 | X2: 0 | Y2: 0 | Z2: 0 | AA2: 0 | AB2: 0 | AC2: 0 | AD2: 0 | AE2: 0 | AF2: 0 | AG2: 0 | AH2: 0 | AI2: 0 | AJ2: 0 | AK2: 0 | AL2: 0 | AM2: 0 | AN2: 0 | AO2: 0 | AP2: 0 | AQ2: 0 | AR2: 0 | AS2: 0
A3: 20602200958 | B3: 1 | C3: 10781 | D3: 0 | E3: 0 | F3: 0 | G3: 0 | H3: 0 | I3: 0 | J3: 0 | K3: 0 | L3: 0 | M3: 0 | N3: 0 | O3: 0 | P3: 0 | Q3: 0 | R3: 0 | S3: 0 | T3: 0 | U3: 0 | V3: 0 | W3: 0 | X3: 0 | Y3: 0 | Z3: 0 | AA3: 0 | AB3: 0 | AC3: 2689.0194 | AD3: 2311.0466 | AE3: 2390.718 | AF3: 2641.8962 | AG3: 2445.6075 | AH3: 2295.1137 | AI3: 2717.1934 | AJ3: 4154.0418 | AK3: 4511.3294 | AL3: 4642.3224 | AM3: 4396.9168 | AN3: 4087.9962 | AO3: 4119.0072 | AP3: 4477.211 | AQ3: 4187.0678 | AR3: 4104.4761 | AS3: 4573.1681
A4: 24082020 | B4: 1 | C4: 10782 | D4: 0 | E4: 0 | F4: 0 | G4: 0 | H4: 0 | I4: 0 | J4: 0 | K4: -13096.79 | L4: 0 | M4: 0 | N4: 0 | O4: 0 | P4: 0 | Q4: 0 | R4: 0 | S4: 0 | T4: 0 | U4: 0 | V4: 0 | W4: 0 | X4: 0 | Y4: 0 | Z4: 0 | AA4: 0 | AB4: 0 | AC4: 0 | AD4: 0 | AE4: 0 | AF4: 0 | AG4: 0 | AH4: 0 | AI4: 0 | AJ4: 0 | AK4: 0 | AL4: 0 | AM4: 0 | AN4: 0 | AO4: 0 | AP4: 0 | AQ4: 0 | AR4: 0 | AS4: 0
A5: AAAG8010092 | B5: 1 | C5: 10783 | D5: 0 | E5: 0 | F5: 0 | G5: 0 | H5: 0 | I5: 0 | J5: 0 | K5: 0 | L5: 0 | M5: 0 | N5: 0 | O5: 0 | P5: 0 | Q5: 0 | R5: 0 | S5: 0 | T5: 0 | U5: 0 | V5: 0 | W5: 0 | X5: 0 | Y5: 0 | Z5: 0 | AA5: 0 | AB5: 0 | AC5: 0 | AD5: 0 | AE5: 0 | AF5: 0 | AG5: 0 | AH5: 0 | AI5: 0 | AJ5: 0 | AK5: 182.33919 | AL5: 182.3324 | AM5: 182.35066 | AN5: 0 | AO5: 226.9164 | AP5: 416.10575 | AQ5: 415.93505 | AR5: 264.66531 | AS5: 113.41037
A6: AAAL6611248 | B6: 1 | C6: 10784 | D6: 0 | E6: 0 | F6: 0 | G6: 0 | H6: 0 | I6: 0 | J6: 0 | K6: 0 | L6: 0 | M6: 0 | N6: 0 | O6: 0 | P6: 0 | Q6: 0 | R6: 0 | S6: 0 | T6: 0 | U6: 0 | V6: 0 | W6: 0 | X6: 0 | Y6: 0 | Z6: 0 | AA6: 0 | AB6: 0 | AC6: 0 | AD6: 0 | AE6: 0 | AF6: 0 | AG6: 0 | AH6: 0 | AI6: 1150.0263 | AJ6: 1299.9267 | AK6: 1150.0262 | AL6: 1100.0477 | AM6: 1100.0385 | AN6: 1036.8256 | AO6: 1088.681 | AP6: 1088.6109 | AQ6: 1088.6938 | AR6: 1088.607 | AS6: 1088.5995
A7: AAG160805FE | B7: 1 | C7: 10785 | D7: 0 | E7: 0 | F7: 0 | G7: 0 | H7: 0 | I7: 0 | J7: 0 | K7: 0 | L7: 0 | M7: 0 | N7: 0 | O7: 0 | P7: 0 | Q7: 0 | R7: 0 | S7: 0 | T7: 0 | U7: 0 | V7: 0 | W7: 0 | X7: 2870.0292 | Y7: 2834.9619 | Z7: 2975.0199 | AA7: 2869.9868 | AB7: 2990.5348 | AC7: 2990.6051 | AD7: 2881.1538 | AE7: 2881.197 | AF7: 2844.7182 | AG7: 2844.6476 | AH7: 2881.2042 | AI7: 2881.2166 | AJ7: 2698.733 | AK7: 2552.9328 | AL7: 2552.8371 | AM7: 2443.5708 | AN7: 2533.9646 | AO7: 2647.4155 | AP7: 2571.7798 | AQ7: 2571.7452 | AR7: 2458.3236 | AS7: 2458.2747
A8: AAGA570212I | B8: 1 | C8: 10786 | D8: 0 | E8: 0 | F8: 0 | G8: 0 | H8: 0 | I8: 0 | J8: 749.9767 | K8: 750.05782 | L8: 750.00757 | M8: 749.99438 | N8: 749.92028 | O8: 749.98824 | P8: 787.55579 | Q8: 787.5344 | R8: 787.4932 | S8: 787.53024 | T8: 787.57368 | U8: 787.42466 | V8: 787.5168 | W8: 787.44136 | X8: 787.496 | Y8: 787.02166 | Z8: 787.58331 | AA8: 787.56177 | AB8: 0 | AC8: 0 | AD8: 562.75884 | AE8: 562.7292 | AF8: 562.72968 | AG8: 562.773 | AH8: 0 | AI8: 0 | AJ8: 0 | AK8: 0 | AL8: 0 | AM8: 0 | AN8: 0 | AO8: 0 | AP8: 0 | AQ8: 0 | AR8: 0 | AS8: 0
A9: AAM970602V7 | B9: 1 | C9: 10787 | D9: 0 | E9: 0 | F9: 0 | G9: 0 | H9: 0 | I9: 0 | J9: 0 | K9: 0 | L9: 0 | M9: 0 | N9: 0 | O9: 0 | P9: 0 | Q9: 0 | R9: 0 | S9: 0 | T9: 0 | U9: 0 | V9: 0 | W9: 0 | X9: 0 | Y9: 0 | Z9: 0 | AA9: 0 | AB9: 0 | AC9: 0 | AD9: 0 | AE9: 0 | AF9: 0 | AG9: 0 | AH9: 0 | AI9: 0 | AJ9: 0 | AK9: 0 | AL9: 0 | AM9: 0 | AN9: 0 | AO9: 1920.0751 | AP9: 1855.9983 | AQ9: 1856.0071 | AR9: 1855.946 | AS9: 1856.0447
A10: AAR160311AL | B10: 1 | C10: 10788 | D10: 6574.1712 | E10: 6574.1448 | F10: 6231.7523 | G10: 6094.7356 | H10: 6300.181 | I10: 6163.1298 | J10: 6163.193 | K10: 7327.4235 | L10: 6985.0294 | M10: 6916.5345 | N10: 6711.081 | O10: 6300.2057 | P10: 13148.078 | Q10: 6437.2006 | R10: 6710.9771 | S10: 6505.5514 | T10: 5752.2551 | U10: 6163.2469 | V10: 6505.6388 | W10: 5889.2523 | X10: 6094.6284 | Y10: 6231.6239 | Z10: 6026.1654 | AA10: 5889.3108 | AB10: 6136.9968 | AC10: 6493.8443 | AD10: 6422.4317 | AE10: 6565.174 | AF10: 6850.597 | AG10: 6850.5337 | AH10: 6779.138 | AI10: 6707.8033 | AJ10: 6921.9354 | AK10: 6993.3526 | AL10: 7064.5551 | AM10: 6779.1646 | AN10: 7472.9371 | AO10: 7843.0246 | AP10: 7546.9416 | AQ10: 7768.9158 | AR10: 7103.0354 | AS10: 7177.0561
A11: AARG6801036 | B11: 1 | C11: 10789 | D11: 0 | E11: 0 | F11: 0 | G11: 0 | H11: 0 | I11: 0 | J11: 1824.0421 | K11: 2279.9815 | L11: 2279.9878 | M11: 2279.9757 | N11: 2280.0467 | O11: 2280.0793 | P11: 2280.083 | Q11: 2280.0377 | R11: 2279.9425 | S11: 2393.9149 | T11: 2393.9188 | U11: 2393.9626 | V11: 2394.0511 | W11: 2394.0518 | X11: 2393.9878 | Y11: 2393.9411 | Z11: 2393.9757 | AA11: 2394.0502 | AB11: 0 | AC11: 2394.0033 | AD11: 0 | AE11: 0 | AF11: 0 | AG11: 0 | AH11: 0 | AI11: 0 | AJ11: 0 | AK11: 0 | AL11: 0 | AM11: 0 | AN11: 0 | AO11: 0 | AP11: 0 | AQ11: 0 | AR11: 0 | AS11: 0
A12: AARG680103H | B12: 1 | C12: 10790 | D12: 0 | E12: 0 | F12: 0 | G12: 0 | H12: 0 | I12: 2250.0179 | J12: 0 | K12: 0 | L12: 0 | M12: 0 | N12: 0 | O12: 0 | P12: 0 | Q12: 0 | R12: 0 | S12: 0 | T12: 0 | U12: 0 | V12: 0 | W12: 0 | X12: 0 | Y12: 0 | Z12: 0 | AA12: 0 | AB12: 0 | AC12: 0 | AD12: 0 | AE12: 0 | AF12: 0 | AG12: 0 | AH12: 0 | AI12: 0 | AJ12: 0 | AK12: 0 | AL12: 0 | AM12: 0 | AN12: 0 | AO12: 0 | AP12: 0 | AQ12: 0 | AR12: 0 | AS12: 0
A13: AAS9610021I | B13: 1 | C13: 10791 | D13: 0 | E13: 0 | F13: 0 | G13: 0 | H13: 0 | I13: 0 | J13: 0 | K13: 0 | L13: 0 | M13: 0 | N13: 0 | O13: 0 | P13: 0 | Q13: 0 | R13: 0 | S13: 0 | T13: 0 | U13: 0 | V13: 0 | W13: 0 | X13: 0 | Y13: 0 | Z13: 0 | AA13: 0 | AB13: 0 | AC13: 0 | AD13: 0 | AE13: 0 | AF13: 0 | AG13: 0 | AH13: 0 | AI13: 0 | AJ13: 0 | AK13: 0 | AL13: 0 | AM13: 0 | AN13: 0 | AO13: 0 | AP13: 0 | AQ13: 0 | AR13: 0 | AS13: 8449.9475
... A784: ZSU920314FC | B784: 1 | C784: 11562 | D784: 0 | E784: 0 | F784: 0 | G784: 0 | H784: 0 | I784: 0 | J784: 0 | K784: 0 | L784: 0 | M784: 0 | N784: 0 | O784: 0 | P784: 0 | Q784: 0 | R784: 0 | S784: 0 | T784: 0 | U784: 0 | V784: 7199.9661 | W784: 7200.0021 | X784: 7200.0759 | Y784: 7200.0655 | Z784: 7200.0911 | AA784: 7199.9577 | AB784: 7199.9488 | AC784: 7200.0763 | AD784: 7199.9248 | AE784: 7199.9576 | AF784: 7200.0838 | AG784: 7199.9062 | AH784: 5363.9119 | AI784: 4859.9329 | AJ784: 5147.9739 | AK784: 5327.988 | AL784: 5471.9898 | AM784: 5616.0048 | AN784: 5898.2172 | AO784: 5972.8193 | AP784: 0 | AQ784: 0 | AR784: 0 | AS784: 0

Sheet NRR Base Mensual
A1: Conglomerado | B1: 2024-01 | C1: 2024-02 | D1: 2024-03 | E1: 2024-04 | F1: 2024-05 | G1: 2024-06 | H1: 2024-07 | I1: 2024-08 | J1: 2024-09 | K1: 2024-10 | L1: 2024-11 | M1: 2024-12 | N1: 2025-01 | O1: 2025-02 | P1: 2025-03 | Q1: 2025-04 | R1: 2025-05 | S1: 2025-06 | T1: 2025-07 | U1: 2025-08 | V1: 2025-09 | W1: 2025-10 | X1: 2025-11 | Y1: 2025-12 | Z1: 2026-01 | AA1: 2026-02 | AB1: 2026-03 | AC1: 2026-04 | AD1: 2026-05 | AE1: 2026-06
A2: 180719670 | B2: =IFERROR(IF('MRR Conglomerado'!D2=0,"",ROUND('MRR Conglomerado'!P2/'MRR Conglomerado'!D2,3)),"") | C2: =IFERROR(IF('MRR Conglomerado'!E2=0,"",ROUND('MRR Conglomerado'!Q2/'MRR Conglomerado'!E2,3)),"") | D2: =IFERROR(IF('MRR Conglomerado'!F2=0,"",ROUND('MRR Conglomerado'!R2/'MRR Conglomerado'!F2,3)),"") | E2: =IFERROR(IF('MRR Conglomerado'!G2=0,"",ROUND('MRR Conglomerado'!S2/'MRR Conglomerado'!G2,3)),"") | F2: =IFERROR(IF('MRR Conglomerado'!H2=0,"",ROUND('MRR Conglomerado'!T2/'MRR Conglomerado'!H2,3)),"") | G2: =IFERROR(IF('MRR Conglomerado'!I2=0,"",ROUND('MRR Conglomerado'!U2/'MRR Conglomerado'!I2,3)),"") | H2: =IFERROR(IF('MRR Conglomerado'!J2=0,"",ROUND('MRR Conglomerado'!V2/'MRR Conglomerado'!J2,3)),"") | I2: =IFERROR(IF('MRR Conglomerado'!K2=0,"",ROUND('MRR Conglomerado'!W2/'MRR Conglomerado'!K2,3)),"") | ... AE2: =IFERROR(IF('MRR Conglomerado'!AG2=0,"",ROUND('MRR Conglomerado'!AS2/'MRR Conglomerado'!AG2,3)),"")
A3: 20602200958 | B3: =IFERROR(IF('MRR Conglomerado'!D3=0,"",ROUND('MRR Conglomerado'!P3/'MRR Conglomerado'!D3,3)),"") | C3: =IFERROR(IF('MRR Conglomerado'!E3=0,"",ROUND('MRR Conglomerado'!Q3/'MRR Conglomerado'!E3,3)),"") | D3: =IFERROR(IF('MRR Conglomerado'!F3=0,"",ROUND('MRR Conglomerado'!R3/'MRR Conglomerado'!F3,3)),"") | E3: =IFERROR(IF('MRR Conglomerado'!G3=0,"",ROUND('MRR Conglomerado'!S3/'MRR Conglomerado'!G3,3)),"") | F3: =IFERROR(IF('MRR Conglomerado'!H3=0,"",ROUND('MRR Conglomerado'!T3/'MRR Conglomerado'!H3,3)),"") | G3: =IFERROR(IF('MRR Conglomerado'!I3=0,"",ROUND('MRR Conglomerado'!U3/'MRR Conglomerado'!I3,3)),"") | H3: =IFERROR(IF('MRR Conglomerado'!J3=0,"",ROUND('MRR Conglomerado'!V3/'MRR Conglomerado'!J3,3)),"") | I3: =IFERROR(IF('MRR Conglomerado'!K3=0,"",ROUND('MRR Conglomerado'!W3/'MRR Conglomerado'!K3,3)),"") | ... AE3: =IFERROR(IF('MRR Conglomerado'!AG3=0,"",ROUND('MRR Conglomerado'!AS3/'MRR Conglomerado'!AG3,3)),"") -> 1.87
A4: 24082020 | B4: =IFERROR(IF('MRR Conglomerado'!D4=0,"",ROUND('MRR Conglomerado'!P4/'MRR Conglomerado'!D4,3)),"") | C4: =IFERROR(IF('MRR Conglomerado'!E4=0,"",ROUND('MRR Conglomerado'!Q4/'MRR Conglomerado'!E4,3)),"") | D4: =IFERROR(IF('MRR Conglomerado'!F4=0,"",ROUND('MRR Conglomerado'!R4/'MRR Conglomerado'!F4,3)),"") | E4: =IFERROR(IF('MRR Conglomerado'!G4=0,"",ROUND('MRR Conglomerado'!S4/'MRR Conglomerado'!G4,3)),"") | F4: =IFERROR(IF('MRR Conglomerado'!H4=0,"",ROUND('MRR Conglomerado'!T4/'MRR Conglomerado'!H4,3)),"") | G4: =IFERROR(IF('MRR Conglomerado'!I4=0,"",ROUND('MRR Conglomerado'!U4/'MRR Conglomerado'!I4,3)),"") | H4: =IFERROR(IF('MRR Conglomerado'!J4=0,"",ROUND('MRR Conglomerado'!V4/'MRR Conglomerado'!J4,3)),"") | I4: =IFERROR(IF('MRR Conglomerado'!K4=0,"",ROUND('MRR Conglomerado'!W4/'MRR Conglomerado'!K4,3)),"") -> 0 | ... AE4: =IFERROR(IF('MRR Conglomerado'!AG4=0,"",ROUND('MRR Conglomerado'!AS4/'MRR Conglomerado'!AG4,3)),"")
A5: AAAG8010092 | B5: =IFERROR(IF('MRR Conglomerado'!D5=0,"",ROUND('MRR Conglomerado'!P5/'MRR Conglomerado'!D5,3)),"") | C5: =IFERROR(IF('MRR Conglomerado'!E5=0,"",ROUND('MRR Conglomerado'!Q5/'MRR Conglomerado'!E5,3)),"") | D5: =IFERROR(IF('MRR Conglomerado'!F5=0,"",ROUND('MRR Conglomerado'!R5/'MRR Conglomerado'!F5,3)),"") | E5: =IFERROR(IF('MRR Conglomerado'!G5=0,"",ROUND('MRR Conglomerado'!S5/'MRR Conglomerado'!G5,3)),"") | F5: =IFERROR(IF('MRR Conglomerado'!H5=0,"",ROUND('MRR Conglomerado'!T5/'MRR Conglomerado'!H5,3)),"") | G5: =IFERROR(IF('MRR Conglomerado'!I5=0,"",ROUND('MRR Conglomerado'!U5/'MRR Conglomerado'!I5,3)),"") | H5: =IFERROR(IF('MRR Conglomerado'!J5=0,"",ROUND('MRR Conglomerado'!V5/'MRR Conglomerado'!J5,3)),"") | I5: =IFERROR(IF('MRR Conglomerado'!K5=0,"",ROUND('MRR Conglomerado'!W5/'MRR Conglomerado'!K5,3)),"") | ... AE5: =IFERROR(IF('MRR Conglomerado'!AG5=0,"",ROUND('MRR Conglomerado'!AS5/'MRR Conglomerado'!AG5,3)),"")
A6: AAAL6611248 | B6: =IFERROR(IF('MRR Conglomerado'!D6=0,"",ROUND('MRR Conglomerado'!P6/'MRR Conglomerado'!D6,3)),"") | C6: =IFERROR(IF('MRR Conglomerado'!E6=0,"",ROUND('MRR Conglomerado'!Q6/'MRR Conglomerado'!E6,3)),"") | D6: =IFERROR(IF('MRR Conglomerado'!F6=0,"",ROUND('MRR Conglomerado'!R6/'MRR Conglomerado'!F6,3)),"") | E6: =IFERROR(IF('MRR Conglomerado'!G6=0,"",ROUND('MRR Conglomerado'!S6/'MRR Conglomerado'!G6,3)),"") | F6: =IFERROR(IF('MRR Conglomerado'!H6=0,"",ROUND('MRR Conglomerado'!T6/'MRR Conglomerado'!H6,3)),"") | G6: =IFERROR(IF('MRR Conglomerado'!I6=0,"",ROUND('MRR Conglomerado'!U6/'MRR Conglomerado'!I6,3)),"") | H6: =IFERROR(IF('MRR Conglomerado'!J6=0,"",ROUND('MRR Conglomerado'!V6/'MRR Conglomerado'!J6,3)),"") | I6: =IFERROR(IF('MRR Conglomerado'!K6=0,"",ROUND('MRR Conglomerado'!W6/'MRR Conglomerado'!K6,3)),"") | ... AE6: =IFERROR(IF('MRR Conglomerado'!AG6=0,"",ROUND('MRR Conglomerado'!AS6/'MRR Conglomerado'!AG6,3)),"")
A7: AAG160805FE | B7: =IFERROR(IF('MRR Conglomerado'!D7=0,"",ROUND('MRR Conglomerado'!P7/'MRR Conglomerado'!D7,3)),"") | C7: =IFERROR(IF('MRR Conglomerado'!E7=0,"",ROUND('MRR Conglomerado'!Q7/'MRR Conglomerado'!E7,3)),"") | D7: =IFERROR(IF('MRR Conglomerado'!F7=0,"",ROUND('MRR Conglomerado'!R7/'MRR Conglomerado'!F7,3)),"") | E7: =IFERROR(IF('MRR Conglomerado'!G7=0,"",ROUND('MRR Conglomerado'!S7/'MRR Conglomerado'!G7,3)),"") | F7: =IFERROR(IF('MRR Conglomerado'!H7=0,"",ROUND('MRR Conglomerado'!T7/'MRR Conglomerado'!H7,3)),"") | G7: =IFERROR(IF('MRR Conglomerado'!I7=0,"",ROUND('MRR Conglomerado'!U7/'MRR Conglomerado'!I7,3)),"") | H7: =IFERROR(IF('MRR Conglomerado'!J7=0,"",ROUND('MRR Conglomerado'!V7/'MRR Conglomerado'!J7,3)),"") | I7: =IFERROR(IF('MRR Conglomerado'!K7=0,"",ROUND('MRR Conglomerado'!W7/'MRR Conglomerado'!K7,3)),"") | ... AE7: =IFERROR(IF('MRR Conglomerado'!AG7=0,"",ROUND('MRR Conglomerado'!AS7/'MRR Conglomerado'!AG7,3)),"") -> 0.864
A8: AAGA570212I | B8: =IFERROR(IF('MRR Conglomerado'!D8=0,"",ROUND('MRR Conglomerado'!P8/'MRR Conglomerado'!D8,3)),"") | C8: =IFERROR(IF('MRR Conglomerado'!E8=0,"",ROUND('MRR Conglomerado'!Q8/'MRR Conglomerado'!E8,3)),"") | D8: =IFERROR(IF('MRR Conglomerado'!F8=0,"",ROUND('MRR Conglomerado'!R8/'MRR Conglomerado'!F8,3)),"") | E8: =IFERROR(IF('MRR Conglomerado'!G8=0,"",ROUND('MRR Conglomerado'!S8/'MRR Conglomerado'!G8,3)),"") | F8: =IFERROR(IF('MRR Conglomerado'!H8=0,"",ROUND('MRR Conglomerado'!T8/'MRR Conglomerado'!H8,3)),"") | G8: =IFERROR(IF('MRR Conglomerado'!I8=0,"",ROUND('MRR Conglomerado'!U8/'MRR Conglomerado'!I8,3)),"") | H8: =IFERROR(IF('MRR Conglomerado'!J8=0,"",ROUND('MRR Conglomerado'!V8/'MRR Conglomerado'!J8,3)),"") -> 1.05 | I8: =IFERROR(IF('MRR Conglomerado'!K8=0,"",ROUND('MRR Conglomerado'!W8/'MRR Conglomerado'!K8,3)),"") -> 1.05 | ... AE8: =IFERROR(IF('MRR Conglomerado'!AG8=0,"",ROUND('MRR Conglomerado'!AS8/'MRR Conglomerado'!AG8,3)),"") -> 0
A9: AAM970602V7 | B9: =IFERROR(IF('MRR Conglomerado'!D9=0,"",ROUND('MRR Conglomerado'!P9/'MRR Conglomerado'!D9,3)),"") | C9: =IFERROR(IF('MRR Conglomerado'!E9=0,"",ROUND('MRR Conglomerado'!Q9/'MRR Conglomerado'!E9,3)),"") | D9: =IFERROR(IF('MRR Conglomerado'!F9=0,"",ROUND('MRR Conglomerado'!R9/'MRR Conglomerado'!F9,3)),"") | E9: =IFERROR(IF('MRR Conglomerado'!G9=0,"",ROUND('MRR Conglomerado'!S9/'MRR Conglomerado'!G9,3)),"") | F9: =IFERROR(IF('MRR Conglomerado'!H9=0,"",ROUND('MRR Conglomerado'!T9/'MRR Conglomerado'!H9,3)),"") | G9: =IFERROR(IF('MRR Conglomerado'!I9=0,"",ROUND('MRR Conglomerado'!U9/'MRR Conglomerado'!I9,3)),"") | H9: =IFERROR(IF('MRR Conglomerado'!J9=0,"",ROUND('MRR Conglomerado'!V9/'MRR Conglomerado'!J9,3)),"") | I9: =IFERROR(IF('MRR Conglomerado'!K9=0,"",ROUND('MRR Conglomerado'!W9/'MRR Conglomerado'!K9,3)),"") | ... AE9: =IFERROR(IF('MRR Conglomerado'!AG9=0,"",ROUND('MRR Conglomerado'!AS9/'MRR Conglomerado'!AG9,3)),"")
A10: AAR160311AL | B10: =IFERROR(IF('MRR Conglomerado'!D10=0,"",ROUND('MRR Conglomerado'!P10/'MRR Conglomerado'!D10,3)),"") -> 2 | C10: =IFERROR(IF('MRR Conglomerado'!E10=0,"",ROUND('MRR Conglomerado'!Q10/'MRR Conglomerado'!E10,3)),"") -> 0.979 | D10: =IFERROR(IF('MRR Conglomerado'!F10=0,"",ROUND('MRR Conglomerado'!R10/'MRR Conglomerado'!F10,3)),"") -> 1.077 | E10: =IFERROR(IF('MRR Conglomerado'!G10=0,"",ROUND('MRR Conglomerado'!S10/'MRR Conglomerado'!G10,3)),"") -> 1.067 | F10: =IFERROR(IF('MRR Conglomerado'!H10=0,"",ROUND('MRR Conglomerado'!T10/'MRR Conglomerado'!H10,3)),"") -> 0.913 | G10: =IFERROR(IF('MRR Conglomerado'!I10=0,"",ROUND('MRR Conglomerado'!U10/'MRR Conglomerado'!I10,3)),"") -> 1 | H10: =IFERROR(IF('MRR Conglomerado'!J10=0,"",ROUND('MRR Conglomerado'!V10/'MRR Conglomerado'!J10,3)),"") -> 1.056 | I10: =IFERROR(IF('MRR Conglomerado'!K10=0,"",ROUND('MRR Conglomerado'!W10/'MRR Conglomerado'!K10,3)),"") -> 0.804 | ... AE10: =IFERROR(IF('MRR Conglomerado'!AG10=0,"",ROUND('MRR Conglomerado'!AS10/'MRR Conglomerado'!AG10,3)),"") -> 1.048
A11: AARG6801036 | B11: =IFERROR(IF('MRR Conglomerado'!D11=0,"",ROUND('MRR Conglomerado'!P11/'MRR Conglomerado'!D11,3)),"") | C11: =IFERROR(IF('MRR Conglomerado'!E11=0,"",ROUND('MRR Conglomerado'!Q11/'MRR Conglomerado'!E11,3)),"") | D11: =IFERROR(IF('MRR Conglomerado'!F11=0,"",ROUND('MRR Conglomerado'!R11/'MRR Conglomerado'!F11,3)),"") | E11: =IFERROR(IF('MRR Conglomerado'!G11=0,"",ROUND('MRR Conglomerado'!S11/'MRR Conglomerado'!G11,3)),"") | F11: =IFERROR(IF('MRR Conglomerado'!H11=0,"",ROUND('MRR Conglomerado'!T11/'MRR Conglomerado'!H11,3)),"") | G11: =IFERROR(IF('MRR Conglomerado'!I11=0,"",ROUND('MRR Conglomerado'!U11/'MRR Conglomerado'!I11,3)),"") | H11: =IFERROR(IF('MRR Conglomerado'!J11=0,"",ROUND('MRR Conglomerado'!V11/'MRR Conglomerado'!J11,3)),"") -> 1.312 | I11: =IFERROR(IF('MRR Conglomerado'!K11=0,"",ROUND('MRR Conglomerado'!W11/'MRR Conglomerado'!K11,3)),"") -> 1.05 | ... AE11: =IFERROR(IF('MRR Conglomerado'!AG11=0,"",ROUND('MRR Conglomerado'!AS11/'MRR Conglomerado'!AG11,3)),"")
A12: AARG680103H | B12: =IFERROR(IF('MRR Conglomerado'!D12=0,"",ROUND('MRR Conglomerado'!P12/'MRR Conglomerado'!D12,3)),"") | C12: =IFERROR(IF('MRR Conglomerado'!E12=0,"",ROUND('MRR Conglomerado'!Q12/'MRR Conglomerado'!E12,3)),"") | D12: =IFERROR(IF('MRR Conglomerado'!F12=0,"",ROUND('MRR Conglomerado'!R12/'MRR Conglomerado'!F12,3)),"") | E12: =IFERROR(IF('MRR Conglomerado'!G12=0,"",ROUND('MRR Conglomerado'!S12/'MRR Conglomerado'!G12,3)),"") | F12: =IFERROR(IF('MRR Conglomerado'!H12=0,"",ROUND('MRR Conglomerado'!T12/'MRR Conglomerado'!H12,3)),"") | G12: =IFERROR(IF('MRR Conglomerado'!I12=0,"",ROUND('MRR Conglomerado'!U12/'MRR Conglomerado'!I12,3)),"") -> 0 | H12: =IFERROR(IF('MRR Conglomerado'!J12=0,"",ROUND('MRR Conglomerado'!V12/'MRR Conglomerado'!J12,3)),"") | I12: =IFERROR(IF('MRR Conglomerado'!K12=0,"",ROUND('MRR Conglomerado'!W12/'MRR Conglomerado'!K12,3)),"") | ... AE12: =IFERROR(IF('MRR Conglomerado'!AG12=0,"",ROUND('MRR Conglomerado'!AS12/'MRR Conglomerado'!AG12,3)),"")
A13: AAS9610021I | B13: =IFERROR(IF('MRR Conglomerado'!D13=0,"",ROUND('MRR Conglomerado'!P13/'MRR Conglomerado'!D13,3)),"") | C13: =IFERROR(IF('MRR Conglomerado'!E13=0,"",ROUND('MRR Conglomerado'!Q13/'MRR Conglomerado'!E13,3)),"") | D13: =IFERROR(IF('MRR Conglomerado'!F13=0,"",ROUND('MRR Conglomerado'!R13/'MRR Conglomerado'!F13,3)),"") | E13: =IFERROR(IF('MRR Conglomerado'!G13=0,"",ROUND('MRR Conglomerado'!S13/'MRR Conglomerado'!G13,3)),"") | F13: =IFERROR(IF('MRR Conglomerado'!H13=0,"",ROUND('MRR Conglomerado'!T13/'MRR Conglomerado'!H13,3)),"") | G13: =IFERROR(IF('MRR Conglomerado'!I13=0,"",ROUND('MRR Conglomerado'!U13/'MRR Conglomerado'!I13,3)),"") | H13: =IFERROR(IF('MRR Conglomerado'!J13=0,"",ROUND('MRR Conglomerado'!V13/'MRR Conglomerado'!J13,3)),"") | I13: =IFERROR(IF('MRR Conglomerado'!K13=0,"",ROUND('MRR Conglomerado'!W13/'MRR Conglomerado'!K13,3)),"") | ... AE13: =IFERROR(IF('MRR Conglomerado'!AG13=0,"",ROUND('MRR Conglomerado'!AS13/'MRR Conglomerado'!AG13,3)),"")
... A784: ZSU920314FC | B784: =IFERROR(IF('MRR Conglomerado'!D784=0,"",ROUND('MRR Conglomerado'!P784/'MRR Conglomerado'!D784,3)),"") | C784: =IFERROR(IF('MRR Conglomerado'!E784=0,"",ROUND('MRR Conglomerado'!Q784/'MRR Conglomerado'!E784,3)),"") | D784: =IFERROR(IF('MRR Conglomerado'!F784=0,"",ROUND('MRR Conglomerado'!R784/'MRR Conglomerado'!F784,3)),"") | E784: =IFERROR(IF('MRR Conglomerado'!G784=0,"",ROUND('MRR Conglomerado'!S784/'MRR Conglomerado'!G784,3)),"") | F784: =IFERROR(IF('MRR Conglomerado'!H784=0,"",ROUND('MRR Conglomerado'!T784/'MRR Conglomerado'!H784,3)),"") | G784: =IFERROR(IF('MRR Conglomerado'!I784=0,"",ROUND('MRR Conglomerado'!U784/'MRR Conglomerado'!I784,3)),"") | H784: =IFERROR(IF('MRR Conglomerado'!J784=0,"",ROUND('MRR Conglomerado'!V784/'MRR Conglomerado'!J784,3)),"") | I784: =IFERROR(IF('MRR Conglomerado'!K784=0,"",ROUND('MRR Conglomerado'!W784/'MRR Conglomerado'!K784,3)),"") | ... AE784: =IFERROR(IF('MRR Conglomerado'!AG784=0,"",ROUND('MRR Conglomerado'!AS784/'MRR Conglomerado'!AG784,3)),"") -> 0

Sheet NRR Base Trimestral
A1: Conglomerado | B1: 2024-04 | C1: 2024-05 | D1: 2024-06 | E1: 2024-07 | F1: 2024-08 | G1: 2024-09 | H1: 2024-10 | I1: 2024-11 | J1: 2024-12 | K1: 2025-01 | L1: 2025-02 | M1: 2025-03 | N1: 2025-04 | O1: 2025-05 | P1: 2025-06 | Q1: 2025-07 | R1: 2025-08 | S1: 2025-09 | T1: 2025-10 | U1: 2025-11 | V1: 2025-12 | W1: 2026-01 | X1: 2026-02 | Y1: 2026-03 | Z1: 2026-04 | AA1: 2026-05 | AB1: 2026-06
A2: 180719670 | B2: =IFERROR(IF(SUM('MRR Conglomerado'!E2:G2)=0,"",ROUND(SUM('MRR Conglomerado'!Q2:S2)/SUM('MRR Conglomerado'!E2:G2),3)),"") | C2: =IFERROR(IF(SUM('MRR Conglomerado'!F2:H2)=0,"",ROUND(SUM('MRR Conglomerado'!R2:T2)/SUM('MRR Conglomerado'!F2:H2),3)),"") | D2: =IFERROR(IF(SUM('MRR Conglomerado'!G2:I2)=0,"",ROUND(SUM('MRR Conglomerado'!S2:U2)/SUM('MRR Conglomerado'!G2:I2),3)),"") | E2: =IFERROR(IF(SUM('MRR Conglomerado'!H2:J2)=0,"",ROUND(SUM('MRR Conglomerado'!T2:V2)/SUM('MRR Conglomerado'!H2:J2),3)),"") | F2: =IFERROR(IF(SUM('MRR Conglomerado'!I2:K2)=0,"",ROUND(SUM('MRR Conglomerado'!U2:W2)/SUM('MRR Conglomerado'!I2:K2),3)),"") | G2: =IFERROR(IF(SUM('MRR Conglomerado'!J2:L2)=0,"",ROUND(SUM('MRR Conglomerado'!V2:X2)/SUM('MRR Conglomerado'!J2:L2),3)),"") | H2: =IFERROR(IF(SUM('MRR Conglomerado'!K2:M2)=0,"",ROUND(SUM('MRR Conglomerado'!W2:Y2)/SUM('MRR Conglomerado'!K2:M2),3)),"") | I2: =IFERROR(IF(SUM('MRR Conglomerado'!L2:N2)=0,"",ROUND(SUM('MRR Conglomerado'!X2:Z2)/SUM('MRR Conglomerado'!L2:N2),3)),"") | ... AB2: =IFERROR(IF(SUM('MRR Conglomerado'!AE2:AG2)=0,"",ROUND(SUM('MRR Conglomerado'!AQ2:AS2)/SUM('MRR Conglomerado'!AE2:AG2),3)),"")
A3: 20602200958 | B3: =IFERROR(IF(SUM('MRR Conglomerado'!E3:G3)=0,"",ROUND(SUM('MRR Conglomerado'!Q3:S3)/SUM('MRR Conglomerado'!E3:G3),3)),"") | C3: =IFERROR(IF(SUM('MRR Conglomerado'!F3:H3)=0,"",ROUND(SUM('MRR Conglomerado'!R3:T3)/SUM('MRR Conglomerado'!F3:H3),3)),"") | D3: =IFERROR(IF(SUM('MRR Conglomerado'!G3:I3)=0,"",ROUND(SUM('MRR Conglomerado'!S3:U3)/SUM('MRR Conglomerado'!G3:I3),3)),"") | E3: =IFERROR(IF(SUM('MRR Conglomerado'!H3:J3)=0,"",ROUND(SUM('MRR Conglomerado'!T3:V3)/SUM('MRR Conglomerado'!H3:J3),3)),"") | F3: =IFERROR(IF(SUM('MRR Conglomerado'!I3:K3)=0,"",ROUND(SUM('MRR Conglomerado'!U3:W3)/SUM('MRR Conglomerado'!I3:K3),3)),"") | G3: =IFERROR(IF(SUM('MRR Conglomerado'!J3:L3)=0,"",ROUND(SUM('MRR Conglomerado'!V3:X3)/SUM('MRR Conglomerado'!J3:L3),3)),"") | H3: =IFERROR(IF(SUM('MRR Conglomerado'!K3:M3)=0,"",ROUND(SUM('MRR Conglomerado'!W3:Y3)/SUM('MRR Conglomerado'!K3:M3),3)),"") | I3: =IFERROR(IF(SUM('MRR Conglomerado'!L3:N3)=0,"",ROUND(SUM('MRR Conglomerado'!X3:Z3)/SUM('MRR Conglomerado'!L3:N3),3)),"") | ... AB3: =IFERROR(IF(SUM('MRR Conglomerado'!AE3:AG3)=0,"",ROUND(SUM('MRR Conglomerado'!AQ3:AS3)/SUM('MRR Conglomerado'!AE3:AG3),3)),"") -> 1.72
A4: 24082020 | B4: =IFERROR(IF(SUM('MRR Conglomerado'!E4:G4)=0,"",ROUND(SUM('MRR Conglomerado'!Q4:S4)/SUM('MRR Conglomerado'!E4:G4),3)),"") | C4: =IFERROR(IF(SUM('MRR Conglomerado'!F4:H4)=0,"",ROUND(SUM('MRR Conglomerado'!R4:T4)/SUM('MRR Conglomerado'!F4:H4),3)),"") | D4: =IFERROR(IF(SUM('MRR Conglomerado'!G4:I4)=0,"",ROUND(SUM('MRR Conglomerado'!S4:U4)/SUM('MRR Conglomerado'!G4:I4),3)),"") | E4: =IFERROR(IF(SUM('MRR Conglomerado'!H4:J4)=0,"",ROUND(SUM('MRR Conglomerado'!T4:V4)/SUM('MRR Conglomerado'!H4:J4),3)),"") | F4: =IFERROR(IF(SUM('MRR Conglomerado'!I4:K4)=0,"",ROUND(SUM('MRR Conglomerado'!U4:W4)/SUM('MRR Conglomerado'!I4:K4),3)),"") -> 0 | G4: =IFERROR(IF(SUM('MRR Conglomerado'!J4:L4)=0,"",ROUND(SUM('MRR Conglomerado'!V4:X4)/SUM('MRR Conglomerado'!J4:L4),3)),"") -> 0 | H4: =IFERROR(IF(SUM('MRR Conglomerado'!K4:M4)=0,"",ROUND(SUM('MRR Conglomerado'!W4:Y4)/SUM('MRR Conglomerado'!K4:M4),3)),"") -> 0 | I4: =IFERROR(IF(SUM('MRR Conglomerado'!L4:N4)=0,"",ROUND(SUM('MRR Conglomerado'!X4:Z4)/SUM('MRR Conglomerado'!L4:N4),3)),"") | ... AB4: =IFERROR(IF(SUM('MRR Conglomerado'!AE4:AG4)=0,"",ROUND(SUM('MRR Conglomerado'!AQ4:AS4)/SUM('MRR Conglomerado'!AE4:AG4),3)),"")
A5: AAAG8010092 | B5: =IFERROR(IF(SUM('MRR Conglomerado'!E5:G5)=0,"",ROUND(SUM('MRR Conglomerado'!Q5:S5)/SUM('MRR Conglomerado'!E5:G5),3)),"") | C5: =IFERROR(IF(SUM('MRR Conglomerado'!F5:H5)=0,"",ROUND(SUM('MRR Conglomerado'!R5:T5)/SUM('MRR Conglomerado'!F5:H5),3)),"") | D5: =IFERROR(IF(SUM('MRR Conglomerado'!G5:I5)=0,"",ROUND(SUM('MRR Conglomerado'!S5:U5)/SUM('MRR Conglomerado'!G5:I5),3)),"") | E5: =IFERROR(IF(SUM('MRR Conglomerado'!H5:J5)=0,"",ROUND(SUM('MRR Conglomerado'!T5:V5)/SUM('MRR Conglomerado'!H5:J5),3)),"") | F5: =IFERROR(IF(SUM('MRR Conglomerado'!I5:K5)=0,"",ROUND(SUM('MRR Conglomerado'!U5:W5)/SUM('MRR Conglomerado'!I5:K5),3)),"") | G5: =IFERROR(IF(SUM('MRR Conglomerado'!J5:L5)=0,"",ROUND(SUM('MRR Conglomerado'!V5:X5)/SUM('MRR Conglomerado'!J5:L5),3)),"") | H5: =IFERROR(IF(SUM('MRR Conglomerado'!K5:M5)=0,"",ROUND(SUM('MRR Conglomerado'!W5:Y5)/SUM('MRR Conglomerado'!K5:M5),3)),"") | I5: =IFERROR(IF(SUM('MRR Conglomerado'!L5:N5)=0,"",ROUND(SUM('MRR Conglomerado'!X5:Z5)/SUM('MRR Conglomerado'!L5:N5),3)),"") | ... AB5: =IFERROR(IF(SUM('MRR Conglomerado'!AE5:AG5)=0,"",ROUND(SUM('MRR Conglomerado'!AQ5:AS5)/SUM('MRR Conglomerado'!AE5:AG5),3)),"")
A6: AAAL6611248 | B6: =IFERROR(IF(SUM('MRR Conglomerado'!E6:G6)=0,"",ROUND(SUM('MRR Conglomerado'!Q6:S6)/SUM('MRR Conglomerado'!E6:G6),3)),"") | C6: =IFERROR(IF(SUM('MRR Conglomerado'!F6:H6)=0,"",ROUND(SUM('MRR Conglomerado'!R6:T6)/SUM('MRR Conglomerado'!F6:H6),3)),"") | D6: =IFERROR(IF(SUM('MRR Conglomerado'!G6:I6)=0,"",ROUND(SUM('MRR Conglomerado'!S6:U6)/SUM('MRR Conglomerado'!G6:I6),3)),"") | E6: =IFERROR(IF(SUM('MRR Conglomerado'!H6:J6)=0,"",ROUND(SUM('MRR Conglomerado'!T6:V6)/SUM('MRR Conglomerado'!H6:J6),3)),"") | F6: =IFERROR(IF(SUM('MRR Conglomerado'!I6:K6)=0,"",ROUND(SUM('MRR Conglomerado'!U6:W6)/SUM('MRR Conglomerado'!I6:K6),3)),"") | G6: =IFERROR(IF(SUM('MRR Conglomerado'!J6:L6)=0,"",ROUND(SUM('MRR Conglomerado'!V6:X6)/SUM('MRR Conglomerado'!J6:L6),3)),"") | H6: =IFERROR(IF(SUM('MRR Conglomerado'!K6:M6)=0,"",ROUND(SUM('MRR Conglomerado'!W6:Y6)/SUM('MRR Conglomerado'!K6:M6),3)),"") | I6: =IFERROR(IF(SUM('MRR Conglomerado'!L6:N6)=0,"",ROUND(SUM('MRR Conglomerado'!X6:Z6)/SUM('MRR Conglomerado'!L6:N6),3)),"") | ... AB6: =IFERROR(IF(SUM('MRR Conglomerado'!AE6:AG6)=0,"",ROUND(SUM('MRR Conglomerado'!AQ6:AS6)/SUM('MRR Conglomerado'!AE6:AG6),3)),"")
A7: AAG160805FE | B7: =IFERROR(IF(SUM('MRR Conglomerado'!E7:G7)=0,"",ROUND(SUM('MRR Conglomerado'!Q7:S7)/SUM('MRR Conglomerado'!E7:G7),3)),"") | C7: =IFERROR(IF(SUM('MRR Conglomerado'!F7:H7)=0,"",ROUND(SUM('MRR Conglomerado'!R7:T7)/SUM('MRR Conglomerado'!F7:H7),3)),"") | D7: =IFERROR(IF(SUM('MRR Conglomerado'!G7:I7)=0,"",ROUND(SUM('MRR Conglomerado'!S7:U7)/SUM('MRR Conglomerado'!G7:I7),3)),"") | E7: =IFERROR(IF(SUM('MRR Conglomerado'!H7:J7)=0,"",ROUND(SUM('MRR Conglomerado'!T7:V7)/SUM('MRR Conglomerado'!H7:J7),3)),"") | F7: =IFERROR(IF(SUM('MRR Conglomerado'!I7:K7)=0,"",ROUND(SUM('MRR Conglomerado'!U7:W7)/SUM('MRR Conglomerado'!I7:K7),3)),"") | G7: =IFERROR(IF(SUM('MRR Conglomerado'!J7:L7)=0,"",ROUND(SUM('MRR Conglomerado'!V7:X7)/SUM('MRR Conglomerado'!J7:L7),3)),"") | H7: =IFERROR(IF(SUM('MRR Conglomerado'!K7:M7)=0,"",ROUND(SUM('MRR Conglomerado'!W7:Y7)/SUM('MRR Conglomerado'!K7:M7),3)),"") | I7: =IFERROR(IF(SUM('MRR Conglomerado'!L7:N7)=0,"",ROUND(SUM('MRR Conglomerado'!X7:Z7)/SUM('MRR Conglomerado'!L7:N7),3)),"") | ... AB7: =IFERROR(IF(SUM('MRR Conglomerado'!AE7:AG7)=0,"",ROUND(SUM('MRR Conglomerado'!AQ7:AS7)/SUM('MRR Conglomerado'!AE7:AG7),3)),"") -> 0.874
A8: AAGA570212I | B8: =IFERROR(IF(SUM('MRR Conglomerado'!E8:G8)=0,"",ROUND(SUM('MRR Conglomerado'!Q8:S8)/SUM('MRR Conglomerado'!E8:G8),3)),"") | C8: =IFERROR(IF(SUM('MRR Conglomerado'!F8:H8)=0,"",ROUND(SUM('MRR Conglomerado'!R8:T8)/SUM('MRR Conglomerado'!F8:H8),3)),"") | D8: =IFERROR(IF(SUM('MRR Conglomerado'!G8:I8)=0,"",ROUND(SUM('MRR Conglomerado'!S8:U8)/SUM('MRR Conglomerado'!G8:I8),3)),"") | E8: =IFERROR(IF(SUM('MRR Conglomerado'!H8:J8)=0,"",ROUND(SUM('MRR Conglomerado'!T8:V8)/SUM('MRR Conglomerado'!H8:J8),3)),"") -> 3.15 | F8: =IFERROR(IF(SUM('MRR Conglomerado'!I8:K8)=0,"",ROUND(SUM('MRR Conglomerado'!U8:W8)/SUM('MRR Conglomerado'!I8:K8),3)),"") -> 1.575 | G8: =IFERROR(IF(SUM('MRR Conglomerado'!J8:L8)=0,"",ROUND(SUM('MRR Conglomerado'!V8:X8)/SUM('MRR Conglomerado'!J8:L8),3)),"") -> 1.05 | H8: =IFERROR(IF(SUM('MRR Conglomerado'!K8:M8)=0,"",ROUND(SUM('MRR Conglomerado'!W8:Y8)/SUM('MRR Conglomerado'!K8:M8),3)),"") -> 1.05 | I8: =IFERROR(IF(SUM('MRR Conglomerado'!L8:N8)=0,"",ROUND(SUM('MRR Conglomerado'!X8:Z8)/SUM('MRR Conglomerado'!L8:N8),3)),"") -> 1.05 | ... AB8: =IFERROR(IF(SUM('MRR Conglomerado'!AE8:AG8)=0,"",ROUND(SUM('MRR Conglomerado'!AQ8:AS8)/SUM('MRR Conglomerado'!AE8:AG8),3)),"") -> 0
A9: AAM970602V7 | B9: =IFERROR(IF(SUM('MRR Conglomerado'!E9:G9)=0,"",ROUND(SUM('MRR Conglomerado'!Q9:S9)/SUM('MRR Conglomerado'!E9:G9),3)),"") | C9: =IFERROR(IF(SUM('MRR Conglomerado'!F9:H9)=0,"",ROUND(SUM('MRR Conglomerado'!R9:T9)/SUM('MRR Conglomerado'!F9:H9),3)),"") | D9: =IFERROR(IF(SUM('MRR Conglomerado'!G9:I9)=0,"",ROUND(SUM('MRR Conglomerado'!S9:U9)/SUM('MRR Conglomerado'!G9:I9),3)),"") | E9: =IFERROR(IF(SUM('MRR Conglomerado'!H9:J9)=0,"",ROUND(SUM('MRR Conglomerado'!T9:V9)/SUM('MRR Conglomerado'!H9:J9),3)),"") | F9: =IFERROR(IF(SUM('MRR Conglomerado'!I9:K9)=0,"",ROUND(SUM('MRR Conglomerado'!U9:W9)/SUM('MRR Conglomerado'!I9:K9),3)),"") | G9: =IFERROR(IF(SUM('MRR Conglomerado'!J9:L9)=0,"",ROUND(SUM('MRR Conglomerado'!V9:X9)/SUM('MRR Conglomerado'!J9:L9),3)),"") | H9: =IFERROR(IF(SUM('MRR Conglomerado'!K9:M9)=0,"",ROUND(SUM('MRR Conglomerado'!W9:Y9)/SUM('MRR Conglomerado'!K9:M9),3)),"") | I9: =IFERROR(IF(SUM('MRR Conglomerado'!L9:N9)=0,"",ROUND(SUM('MRR Conglomerado'!X9:Z9)/SUM('MRR Conglomerado'!L9:N9),3)),"") | ... AB9: =IFERROR(IF(SUM('MRR Conglomerado'!AE9:AG9)=0,"",ROUND(SUM('MRR Conglomerado'!AQ9:AS9)/SUM('MRR Conglomerado'!AE9:AG9),3)),"")
A10: AAR160311AL | B10: =IFERROR(IF(SUM('MRR Conglomerado'!E10:G10)=0,"",ROUND(SUM('MRR Conglomerado'!Q10:S10)/SUM('MRR Conglomerado'!E10:G10),3)),"") -> 1.04 | C10: =IFERROR(IF(SUM('MRR Conglomerado'!F10:H10)=0,"",ROUND(SUM('MRR Conglomerado'!R10:T10)/SUM('MRR Conglomerado'!F10:H10),3)),"") -> 1.018 | D10: =IFERROR(IF(SUM('MRR Conglomerado'!G10:I10)=0,"",ROUND(SUM('MRR Conglomerado'!S10:U10)/SUM('MRR Conglomerado'!G10:I10),3)),"") -> 0.993 | E10: =IFERROR(IF(SUM('MRR Conglomerado'!H10:J10)=0,"",ROUND(SUM('MRR Conglomerado'!T10:V10)/SUM('MRR Conglomerado'!H10:J10),3)),"") -> 0.989 | F10: =IFERROR(IF(SUM('MRR Conglomerado'!I10:K10)=0,"",ROUND(SUM('MRR Conglomerado'!U10:W10)/SUM('MRR Conglomerado'!I10:K10),3)),"") -> 0.944 | G10: =IFERROR(IF(SUM('MRR Conglomerado'!J10:L10)=0,"",ROUND(SUM('MRR Conglomerado'!V10:X10)/SUM('MRR Conglomerado'!J10:L10),3)),"") -> 0.903 | H10: =IFERROR(IF(SUM('MRR Conglomerado'!K10:M10)=0,"",ROUND(SUM('MRR Conglomerado'!W10:Y10)/SUM('MRR Conglomerado'!K10:M10),3)),"") -> 0.858 | I10: =IFERROR(IF(SUM('MRR Conglomerado'!L10:N10)=0,"",ROUND(SUM('MRR Conglomerado'!X10:Z10)/SUM('MRR Conglomerado'!L10:N10),3)),"") -> 0.89 | ... AB10: =IFERROR(IF(SUM('MRR Conglomerado'!AE10:AG10)=0,"",ROUND(SUM('MRR Conglomerado'!AQ10:AS10)/SUM('MRR Conglomerado'!AE10:AG10),3)),"") -> 1.088
A11: AARG6801036 | B11: =IFERROR(IF(SUM('MRR Conglomerado'!E11:G11)=0,"",ROUND(SUM('MRR Conglomerado'!Q11:S11)/SUM('MRR Conglomerado'!E11:G11),3)),"") | C11: =IFERROR(IF(SUM('MRR Conglomerado'!F11:H11)=0,"",ROUND(SUM('MRR Conglomerado'!R11:T11)/SUM('MRR Conglomerado'!F11:H11),3)),"") | D11: =IFERROR(IF(SUM('MRR Conglomerado'!G11:I11)=0,"",ROUND(SUM('MRR Conglomerado'!S11:U11)/SUM('MRR Conglomerado'!G11:I11),3)),"") | E11: =IFERROR(IF(SUM('MRR Conglomerado'!H11:J11)=0,"",ROUND(SUM('MRR Conglomerado'!T11:V11)/SUM('MRR Conglomerado'!H11:J11),3)),"") -> 3.937 | F11: =IFERROR(IF(SUM('MRR Conglomerado'!I11:K11)=0,"",ROUND(SUM('MRR Conglomerado'!U11:W11)/SUM('MRR Conglomerado'!I11:K11),3)),"") -> 1.75 | G11: =IFERROR(IF(SUM('MRR Conglomerado'!J11:L11)=0,"",ROUND(SUM('MRR Conglomerado'!V11:X11)/SUM('MRR Conglomerado'!J11:L11),3)),"") -> 1.125 | H11: =IFERROR(IF(SUM('MRR Conglomerado'!K11:M11)=0,"",ROUND(SUM('MRR Conglomerado'!W11:Y11)/SUM('MRR Conglomerado'!K11:M11),3)),"") -> 1.05 | I11: =IFERROR(IF(SUM('MRR Conglomerado'!L11:N11)=0,"",ROUND(SUM('MRR Conglomerado'!X11:Z11)/SUM('MRR Conglomerado'!L11:N11),3)),"") -> 1.05 | ... AB11: =IFERROR(IF(SUM('MRR Conglomerado'!AE11:AG11)=0,"",ROUND(SUM('MRR Conglomerado'!AQ11:AS11)/SUM('MRR Conglomerado'!AE11:AG11),3)),"")
A12: AARG680103H | B12: =IFERROR(IF(SUM('MRR Conglomerado'!E12:G12)=0,"",ROUND(SUM('MRR Conglomerado'!Q12:S12)/SUM('MRR Conglomerado'!E12:G12),3)),"") | C12: =IFERROR(IF(SUM('MRR Conglomerado'!F12:H12)=0,"",ROUND(SUM('MRR Conglomerado'!R12:T12)/SUM('MRR Conglomerado'!F12:H12),3)),"") | D12: =IFERROR(IF(SUM('MRR Conglomerado'!G12:I12)=0,"",ROUND(SUM('MRR Conglomerado'!S12:U12)/SUM('MRR Conglomerado'!G12:I12),3)),"") -> 0 | E12: =IFERROR(IF(SUM('MRR Conglomerado'!H12:J12)=0,"",ROUND(SUM('MRR Conglomerado'!T12:V12)/SUM('MRR Conglomerado'!H12:J12),3)),"") -> 0 | F12: =IFERROR(IF(SUM('MRR Conglomerado'!I12:K12)=0,"",ROUND(SUM('MRR Conglomerado'!U12:W12)/SUM('MRR Conglomerado'!I12:K12),3)),"") -> 0 | G12: =IFERROR(IF(SUM('MRR Conglomerado'!J12:L12)=0,"",ROUND(SUM('MRR Conglomerado'!V12:X12)/SUM('MRR Conglomerado'!J12:L12),3)),"") | H12: =IFERROR(IF(SUM('MRR Conglomerado'!K12:M12)=0,"",ROUND(SUM('MRR Conglomerado'!W12:Y12)/SUM('MRR Conglomerado'!K12:M12),3)),"") | I12: =IFERROR(IF(SUM('MRR Conglomerado'!L12:N12)=0,"",ROUND(SUM('MRR Conglomerado'!X12:Z12)/SUM('MRR Conglomerado'!L12:N12),3)),"") | ... AB12: =IFERROR(IF(SUM('MRR Conglomerado'!AE12:AG12)=0,"",ROUND(SUM('MRR Conglomerado'!AQ12:AS12)/SUM('MRR Conglomerado'!AE12:AG12),3)),"")
