Workbook

Sheet Resumen
A1: MÉXICO — NRR DE JUNIO 2026, BASE MENSUAL, POR SEGMENTO DE TAMAÑO
A2: NRR del mes X = MRR de la cohorte en X / MRR en X-12 (cohorte = conglomerados de México con MRR > 0 en X-12; los creados después quedan fuera). Todo en MXN; USD sólo para segmentar (TC del mes base). Fuga = MRR actual = 0. GRR = MIN(actual; base) / base (retención sin expansión).
B4: NRR 2026-06 (vs 2025-06)
A5: Segmento | B5: N | C5: Fuga (n) | D5: % Fuga | E5: GRR | F5: NRR
A6: Menos de 100 USD | B6: =COUNTIFS('Detalle 2026-06'!C2:C784,">0",'Detalle 2026-06'!G2:G784,"Menos de 100 USD") -> 125 | C6: =COUNTIFS('Detalle 2026-06'!C2:C784,">0",'Detalle 2026-06'!D2:D784,"<=0",'Detalle 2026-06'!G2:G784,"Menos de 100 USD") -> 46 | D6: =IFERROR(COUNTIFS('Detalle 2026-06'!C2:C784,">0",'Detalle 2026-06'!D2:D784,"<=0",'Detalle 2026-06'!G2:G784,"Menos de 100 USD")/COUNTIFS('Detalle 2026-06'!C2:C784,">0",'Detalle 2026-06'!G2:G784,"Menos de 100 USD"),"") -> 0.368 | E6: =IFERROR(SUMIFS('Detalle 2026-06'!H2:H784,'Detalle 2026-06'!G2:G784,"Menos de 100 USD")/SUMIFS('Detalle 2026-06'!C2:C784,'Detalle 2026-06'!G2:G784,"Menos de 100 USD"),"") -> 0.65358351 | F6: =IFERROR(SUMIFS('Detalle 2026-06'!D2:D784,'Detalle 2026-06'!G2:G784,"Menos de 100 USD")/SUMIFS('Detalle 2026-06'!C2:C784,'Detalle 2026-06'!G2:G784,"Menos de 100 USD"),"") -> 0.91827528
A7: 100 a 500 USD | B7: =COUNTIFS('Detalle 2026-06'!C2:C784,">0",'Detalle 2026-06'!G2:G784,"100 a 500 USD") -> 166 | C7: =COUNTIFS('Detalle 2026-06'!C2:C784,">0",'Detalle 2026-06'!D2:D784,"<=0",'Detalle 2026-06'!G2:G784,"100 a 500 USD") -> 31 | D7: =IFERROR(COUNTIFS('Detalle 2026-06'!C2:C784,">0",'Detalle 2026-06'!D2:D784,"<=0",'Detalle 2026-06'!G2:G784,"100 a 500 USD")/COUNTIFS('Detalle 2026-06'!C2:C784,">0",'Detalle 2026-06'!G2:G784,"100 a 500 USD"),"") -> 0.18674699 | E7: =IFERROR(SUMIFS('Detalle 2026-06'!H2:H784,'Detalle 2026-06'!G2:G784,"100 a 500 USD")/SUMIFS('Detalle 2026-06'!C2:C784,'Detalle 2026-06'!G2:G784,"100 a 500 USD"),"") -> 0.71604021 | F7: =IFERROR(SUMIFS('Detalle 2026-06'!D2:D784,'Detalle 2026-06'!G2:G784,"100 a 500 USD")/SUMIFS('Detalle 2026-06'!C2:C784,'Detalle 2026-06'!G2:G784,"100 a 500 USD"),"") -> 0.93279317
A8: 500 a 2.000 USD | B8: =COUNTIFS('Detalle 2026-06'!C2:C784,">0",'Detalle 2026-06'!G2:G784,"500 a 2.000 USD") -> 51 | C8: =COUNTIFS('Detalle 2026-06'!C2:C784,">0",'Detalle 2026-06'!D2:D784,"<=0",'Detalle 2026-06'!G2:G784,"500 a 2.000 USD") -> 9 | D8: =IFERROR(COUNTIFS('Detalle 2026-06'!C2:C784,">0",'Detalle 2026-06'!D2:D784,"<=0",'Detalle 2026-06'!G2:G784,"500 a 2.000 USD")/COUNTIFS('Detalle 2026-06'!C2:C784,">0",'Detalle 2026-06'!G2:G784,"500 a 2.000 USD"),"") -> 0.17647059 | E8: =IFERROR(SUMIFS('Detalle 2026-06'!H2:H784,'Detalle 2026-06'!G2:G784,"500 a 2.000 USD")/SUMIFS('Detalle 2026-06'!C2:C784,'Detalle 2026-06'!G2:G784,"500 a 2.000 USD"),"") -> 0.75998045 | F8: =IFERROR(SUMIFS('Detalle 2026-06'!D2:D784,'Detalle 2026-06'!G2:G784,"500 a 2.000 USD")/SUMIFS('Detalle 2026-06'!C2:C784,'Detalle 2026-06'!G2:G784,"500 a 2.000 USD"),"") -> 0.93446329
A9: Más de 2.000 USD | B9: =COUNTIFS('Detalle 2026-06'!C2:C784,">0",'Detalle 2026-06'!G2:G784,"Más de 2.000 USD") -> 5 | C9: =COUNTIFS('Detalle 2026-06'!C2:C784,">0",'Detalle 2026-06'!D2:D784,"<=0",'Detalle 2026-06'!G2:G784,"Más de 2.000 USD") -> 0 | D9: =IFERROR(COUNTIFS('Detalle 2026-06'!C2:C784,">0",'Detalle 2026-06'!D2:D784,"<=0",'Detalle 2026-06'!G2:G784,"Más de 2.000 USD")/COUNTIFS('Detalle 2026-06'!C2:C784,">0",'Detalle 2026-06'!G2:G784,"Más de 2.000 USD"),"") -> 0 | E9: =IFERROR(SUMIFS('Detalle 2026-06'!H2:H784,'Detalle 2026-06'!G2:G784,"Más de 2.000 USD")/SUMIFS('Detalle 2026-06'!C2:C784,'Detalle 2026-06'!G2:G784,"Más de 2.000 USD"),"") -> 0.99479938 | F9: =IFERROR(SUMIFS('Detalle 2026-06'!D2:D784,'Detalle 2026-06'!G2:G784,"Más de 2.000 USD")/SUMIFS('Detalle 2026-06'!C2:C784,'Detalle 2026-06'!G2:G784,"Más de 2.000 USD"),"") -> 1.281245
A10: Total México | B10: =COUNTIFS('Detalle 2026-06'!C2:C784,">0") -> 347 | C10: =COUNTIFS('Detalle 2026-06'!C2:C784,">0",'Detalle 2026-06'!D2:D784,"<=0") -> 86 | D10: =IFERROR(COUNTIFS('Detalle 2026-06'!C2:C784,">0",'Detalle 2026-06'!D2:D784,"<=0")/COUNTIFS('Detalle 2026-06'!C2:C784,">0"),"") -> 0.24783862 | E10: =IFERROR(SUM('Detalle 2026-06'!H2:H784)/SUM('Detalle 2026-06'!C2:C784),"") -> 0.76716609 | F10: =IFERROR(SUM('Detalle 2026-06'!D2:D784)/SUM('Detalle 2026-06'!C2:C784),"") -> 0.97602044

Sheet MRR Conglomerado
A1: Conglomerado | B1: Empresa(s) (Cliente) | C1: N° RUTs | D1: Filas en MRR_a_junio_26 (Moneda Loca v2) | E1: 2023-01 | F1: 2023-02 | G1: 2023-03 | H1: 2023-04 | I1: 2023-05 | J1: 2023-06 | K1: 2023-07 | L1: 2023-08 | M1: 2023-09 | N1: 2023-10 | O1: 2023-11 | P1: 2023-12 | Q1: 2024-01 | R1: 2024-02 | S1: 2024-03 | T1: 2024-04 | U1: 2024-05 | V1: 2024-06 | W1: 2024-07 | X1: 2024-08 | Y1: 2024-09 | Z1: 2024-10 | AA1: 2024-11 | AB1: 2024-12 | AC1: 2025-01 | AD1: 2025-02 | AE1: 2025-03 | AF1: 2025-04 | AG1: 2025-05 | AH1: 2025-06 | AI1: 2025-07 | AJ1: 2025-08 | AK1: 2025-09 | AL1: 2025-10 | AM1: 2025-11 | AN1: 2025-12 | AO1: 2026-01 | AP1: 2026-02 | AQ1: 2026-03 | AR1: 2026-04 | AS1: 2026-05 | AT1: 2026-06
A2: 180719670 | B2: SERVICIOS DE ADMINISTRACION GARFLO S.C. | C2: 1 | D2: 10780 | E2: 0 | F2: 0 | G2: 0 | H2: 0 | I2: 0 | J2: 0 | K2: 0 | L2: 0 | M2: 0 | N2: 0 | O2: 0 | P2: 0 | Q2: 0 | R2: 0 | S2: 0 | T2: 0 | U2: 0 | V2: 0 | W2: 0 | X2: 0 | Y2: 0 | Z2: 0 | AA2: 0 | AB2: 0 | AC2: 0 | AD2: 0 | AE2: 0 | AF2: 0 | AG2: 0 | AH2: 0 | AI2: 0 | AJ2: 0 | AK2: 0 | AL2: 0 | AM2: 0 | AN2: 0 | AO2: 0 | AP2: 0 | AQ2: 0 | AR2: 0 | AS2: 0 | AT2: 0
A3: 20602200958 | B3: VISMA ENTERPRISE SAC | C3: 1 | D3: 10781 | E3: 0 | F3: 0 | G3: 0 | H3: 0 | I3: 0 | J3: 0 | K3: 0 | L3: 0 | M3: 0 | N3: 0 | O3: 0 | P3: 0 | Q3: 0 | R3: 0 | S3: 0 | T3: 0 | U3: 0 | V3: 0 | W3: 0 | X3: 0 | Y3: 0 | Z3: 0 | AA3: 0 | AB3: 0 | AC3: 0 | AD3: 2689.0194 | AE3: 2311.0466 | AF3: 2390.718 | AG3: 2641.8962 | AH3: 2445.6075 | AI3: 2295.1137 | AJ3: 2717.1934 | AK3: 4154.0418 | AL3: 4511.3294 | AM3: 4642.3224 | AN3: 4396.9168 | AO3: 4087.9962 | AP3: 4119.0072 | AQ3: 4477.211 | AR3: 4187.0678 | AS3: 4104.4761 | AT3: 4573.1681
A4: 24082020 | B4: BANKAYA SAPI DE CV | C4: 1 | D4: 10782 | E4: 0 | F4: 0 | G4: 0 | H4: 0 | I4: 0 | J4: 0 | K4: 0 | L4: -13096.79 | M4: 0 | N4: 0 | O4: 0 | P4: 0 | Q4: 0 | R4: 0 | S4: 0 | T4: 0 | U4: 0 | V4: 0 | W4: 0 | X4: 0 | Y4: 0 | Z4: 0 | AA4: 0 | AB4: 0 | AC4: 0 | AD4: 0 | AE4: 0 | AF4: 0 | AG4: 0 | AH4: 0 | AI4: 0 | AJ4: 0 | AK4: 0 | AL4: 0 | AM4: 0 | AN4: 0 | AO4: 0 | AP4: 0 | AQ4: 0 | AR4: 0 | AS4: 0 | AT4: 0
A5: AAAG8010092 | B5: GIORDANO AYALA ARIAS | C5: 1 | D5: 10783 | E5: 0 | F5: 0 | G5: 0 | H5: 0 | I5: 0 | J5: 0 | K5: 0 | L5: 0 | M5: 0 | N5: 0 | O5: 0 | P5: 0 | Q5: 0 | R5: 0 | S5: 0 | T5: 0 | U5: 0 | V5: 0 | W5: 0 | X5: 0 | Y5: 0 | Z5: 0 | AA5: 0 | AB5: 0 | AC5: 0 | AD5: 0 | AE5: 0 | AF5: 0 | AG5: 0 | AH5: 0 | AI5: 0 | AJ5: 0 | AK5: 0 | AL5: 182.33919 | AM5: 182.3324 | AN5: 182.35066 | AO5: 0 | AP5: 226.9164 | AQ5: 416.10575 | AR5: 415.93505 | AS5: 264.66531 | AT5: 113.41037
A6: AAAL6611248 | B6: LETICIA ALMAZAN ARELLANO | C6: 1 | D6: 10784 | E6: 0 | F6: 0 | G6: 0 | H6: 0 | I6: 0 | J6: 0 | K6: 0 | L6: 0 | M6: 0 | N6: 0 | O6: 0 | P6: 0 | Q6: 0 | R6: 0 | S6: 0 | T6: 0 | U6: 0 | V6: 0 | W6: 0 | X6: 0 | Y6: 0 | Z6: 0 | AA6: 0 | AB6: 0 | AC6: 0 | AD6: 0 | AE6: 0 | AF6: 0 | AG6: 0 | AH6: 0 | AI6: 0 | AJ6: 1150.0263 | AK6: 1299.9267 | AL6: 1150.0262 | AM6: 1100.0477 | AN6: 1100.0385 | AO6: 1036.8256 | AP6: 1088.681 | AQ6: 1088.6109 | AR6: 1088.6938 | AS6: 1088.607 | AT6: 1088.5995
A7: AAG160805FE | B7: ABASTECEDORA AGRICENTER | C7: 1 | D7: 10785 | E7: 0 | F7: 0 | G7: 0 | H7: 0 | I7: 0 | J7: 0 | K7: 0 | L7: 0 | M7: 0 | N7: 0 | O7: 0 | P7: 0 | Q7: 0 | R7: 0 | S7: 0 | T7: 0 | U7: 0 | V7: 0 | W7: 0 | X7: 0 | Y7: 2870.0292 | Z7: 2834.9619 | AA7: 2975.0199 | AB7: 2869.9868 | AC7: 2990.5348 | AD7: 2990.6051 | AE7: 2881.1538 | AF7: 2881.197 | AG7: 2844.7182 | AH7: 2844.6476 | AI7: 2881.2042 | AJ7: 2881.2166 | AK7: 2698.733 | AL7: 2552.9328 | AM7: 2552.8371 | AN7: 2443.5708 | AO7: 2533.9646 | AP7: 2647.4155 | AQ7: 2571.7798 | AR7: 2571.7452 | AS7: 2458.3236 | AT7: 2458.2747
A8: AAGA570212I | B8: ARTURO ALMARAZ GARCIA | C8: 1 | D8: 10786 | E8: 0 | F8: 0 | G8: 0 | H8: 0 | I8: 0 | J8: 0 | K8: 749.9767 | L8: 750.05782 | M8: 750.00757 | N8: 749.99438 | O8: 749.92028 | P8: 749.98824 | Q8: 787.55579 | R8: 787.5344 | S8: 787.4932 | T8: 787.53024 | U8: 787.57368 | V8: 787.42466 | W8: 787.5168 | X8: 787.44136 | Y8: 787.496 | Z8: 787.02166 | AA8: 787.58331 | AB8: 787.56177 | AC8: 0 | AD8: 0 | AE8: 562.75884 | AF8: 562.7292 | AG8: 562.72968 | AH8: 562.773 | AI8: 0 | AJ8: 0 | AK8: 0 | AL8: 0 | AM8: 0 | AN8: 0 | AO8: 0 | AP8: 0 | AQ8: 0 | AR8: 0 | AS8: 0 | AT8: 0
A9: AAM970602V7 | B9: ANALISIS AMBIENTAL | C9: 1 | D9: 10787 | E9: 0 | F9: 0 | G9: 0 | H9: 0 | I9: 0 | J9: 0 | K9: 0 | L9: 0 | M9: 0 | N9: 0 | O9: 0 | P9: 0 | Q9: 0 | R9: 0 | S9: 0 | T9: 0 | U9: 0 | V9: 0 | W9: 0 | X9: 0 | Y9: 0 | Z9: 0 | AA9: 0 | AB9: 0 | AC9: 0 | AD9: 0 | AE9: 0 | AF9: 0 | AG9: 0 | AH9: 0 | AI9: 0 | AJ9: 0 | AK9: 0 | AL9: 0 | AM9: 0 | AN9: 0 | AO9: 0 | AP9: 1920.0751 | AQ9: 1855.9983 | AR9: 1856.0071 | AS9: 1855.946 | AT9: 1856.0447
A10: AAR160311AL | B10: ALIMENTOS AREM | C10: 1 | D10: 10788 | E10: 6574.1712 | F10: 6574.1448 | G10: 6231.7523 | H10: 6094.7356 | I10: 6300.181 | J10: 6163.1298 | K10: 6163.193 | L10: 7327.4235 | M10: 6985.0294 | N10: 6916.5345 | O10: 6711.081 | P10: 6300.2057 | Q10: 13148.078 | R10: 6437.2006 | S10: 6710.9771 | T10: 6505.5514 | U10: 5752.2551 | V10: 6163.2469 | W10: 6505.6388 | X10: 5889.2523 | Y10: 6094.6284 | Z10: 6231.6239 | AA10: 6026.1654 | AB10: 5889.3108 | AC10: 6136.9968 | AD10: 6493.8443 | AE10: 6422.4317 | AF10: 6565.174 | AG10: 6850.597 | AH10: 6850.5337 | AI10: 6779.138 | AJ10: 6707.8033 | AK10: 6921.9354 | AL10: 6993.3526 | AM10: 7064.5551 | AN10: 6779.1646 | AO10: 7472.9371 | AP10: 7843.0246 | AQ10: 7546.9416 | AR10: 7768.9158 | AS10: 7103.0354 | AT10: 7177.0561
A11: AARG6801036 | B11: GERARDO FILADELFO ALVAREZ ROSAS | C11: 1 | D11: 10789 | E11: 0 | F11: 0 | G11: 0 | H11: 0 | I11: 0 | J11: 0 | K11: 1824.0421 | L11: 2279.9815 | M11: 2279.9878 | N11: 2279.9757 | O11: 2280.0467 | P11: 2280.0793 | Q11: 2280.083 | R11: 2280.0377 | S11: 2279.9425 | T11: 2393.9149 | U11: 2393.9188 | V11: 2393.9626 | W11: 2394.0511 | X11: 2394.0518 | Y11: 2393.9878 | Z11: 2393.9411 | AA11: 2393.9757 | AB11: 2394.0502 | AC11: 0 | AD11: 2394.0033 | AE11: 0 | AF11: 0 | AG11: 0 | AH11: 0 | AI11: 0 | AJ11: 0 | AK11: 0 | AL11: 0 | AM11: 0 | AN11: 0 | AO11: 0 | AP11: 0 | AQ11: 0 | AR11: 0 | AS11: 0 | AT11: 0
A12: AARG680103H | B12: GERARDO FILADELFO ALVAREZ ROSAS | C12: 1 | D12: 10790 | E12: 0 | F12: 0 | G12: 0 | H12: 0 | I12: 0 | J12: 2250.0179 | K12: 0 | L12: 0 | M12: 0 | N12: 0 | O12: 0 | P12: 0 | Q12: 0 | R12: 0 | S12: 0 | T12: 0 | U12: 0 | V12: 0 | W12: 0 | X12: 0 | Y12: 0 | Z12: 0 | AA12: 0 | AB12: 0 | AC12: 0 | AD12: 0 | AE12: 0 | AF12: 0 | AG12: 0 | AH12: 0 | AI12: 0 | AJ12: 0 | AK12: 0 | AL12: 0 | AM12: 0 | AN12: 0 | AO12: 0 | AP12: 0 | AQ12: 0 | AR12: 0 | AS12: 0 | AT12: 0
A13: AAS9610021I | B13: ANCORA AGENTE DE SEGUROS Y DE FIANZAS | C13: 1 | D13: 10791 | E13: 0 | F13: 0 | G13: 0 | H13: 0 | I13: 0 | J13: 0 | K13: 0 | L13: 0 | M13: 0 | N13: 0 | O13: 0 | P13: 0 | Q13: 0 | R13: 0 | S13: 0 | T13: 0 | U13: 0 | V13: 0 | W13: 0 | X13: 0 | Y13: 0 | Z13: 0 | AA13: 0 | AB13: 0 | AC13: 0 | AD13: 0 | AE13: 0 | AF13: 0 | AG13: 0 | AH13: 0 | AI13: 0 | AJ13: 0 | AK13: 0 | AL13: 0 | AM13: 0 | AN13: 0 | AO13: 0 | AP13: 0 | AQ13: 0 | AR13: 0 | AS13: 0 | AT13: 8449.9475
... A784: ZSU920314FC | B784: ZAPATERIAS SUPER | C784: 1 | D784: 11562 | E784: 0 | F784: 0 | G784: 0 | H784: 0 | I784: 0 | J784: 0 | K784: 0 | L784: 0 | M784: 0 | N784: 0 | O784: 0 | P784: 0 | Q784: 0 | R784: 0 | S784: 0 | T784: 0 | U784: 0 | V784: 0 | W784: 7199.9661 | X784: 7200.0021 | Y784: 7200.0759 | Z784: 7200.0655 | AA784: 7200.0911 | AB784: 7199.9577 | AC784: 7199.9488 | AD784: 7200.0763 | AE784: 7199.9248 | AF784: 7199.9576 | AG784: 7200.0838 | AH784: 7199.9062 | AI784: 5363.9119 | AJ784: 4859.9329 | AK784: 5147.9739 | AL784: 5327.988 | AM784: 5471.9898 | AN784: 5616.0048 | AO784: 5898.2172 | AP784: 5972.8193 | AQ784: 0 | AR784: 0 | AS784: 0 | AT784: 0

Sheet Detalle 2026-06
A1: Conglomerado | B1: TC MXN/USD mes base (sólo tamaño) | C1: MRR 2025-06 MXN (base) | D1: MRR 2026-06 MXN (actual) | E1: NRR (MXN) | F1: Tamaño USD (base/TC) | G1: Segmento | H1: MRR retenido MXN (=MIN(actual;base))
A2: 180719670 | B2: 18.885 | C2: =IF('MRR Conglomerado'!AH2>0,'MRR Conglomerado'!AH2,"") | D2: =IF(C2="","",'MRR Conglomerado'!AT2) | E2: =IF(C2="","",D2/C2) | F2: =IF(C2="","",C2/B2) | G2: =IF(F2="","",IF(F2<100,"Menos de 100 USD",IF(F2<500,"100 a 500 USD",IF(F2<2000,"500 a 2.000 USD","Más de 2.000 USD")))) | H2: =IF(C2="","",MIN(D2,C2))
A3: 20602200958 | B3: 18.885 | C3: =IF('MRR Conglomerado'!AH3>0,'MRR Conglomerado'!AH3,"") -> 2445.6075 | D3: =IF(C3="","",'MRR Conglomerado'!AT3) -> 4573.1681 | E3: =IF(C3="","",D3/C3) -> 1.8699518 | F3: =IF(C3="","",C3/B3) -> 129.5 | G3: =IF(F3="","",IF(F3<100,"Menos de 100 USD",IF(F3<500,"100 a 500 USD",IF(F3<2000,"500 a 2.000 USD","Más de 2.000 USD")))) -> 100 a 500 USD | H3: =IF(C3="","",MIN(D3,C3)) -> 2445.6075
A4: 24082020 | B4: 18.885 | C4: =IF('MRR Conglomerado'!AH4>0,'MRR Conglomerado'!AH4,"") | D4: =IF(C4="","",'MRR Conglomerado'!AT4) | E4: =IF(C4="","",D4/C4) | F4: =IF(C4="","",C4/B4) | G4: =IF(F4="","",IF(F4<100,"Menos de 100 USD",IF(F4<500,"100 a 500 USD",IF(F4<2000,"500 a 2.000 USD","Más de 2.000 USD")))) | H4: =IF(C4="","",MIN(D4,C4))
A5: AAAG8010092 | B5: 18.885 | C5: =IF('MRR Conglomerado'!AH5>0,'MRR Conglomerado'!AH5,"") | D5: =IF(C5="","",'MRR Conglomerado'!AT5) | E5: =IF(C5="","",D5/C5) | F5: =IF(C5="","",C5/B5) | G5: =IF(F5="","",IF(F5<100,"Menos de 100 USD",IF(F5<500,"100 a 500 USD",IF(F5<2000,"500 a 2.000 USD","Más de 2.000 USD")))) | H5: =IF(C5="","",MIN(D5,C5))
A6: AAAL6611248 | B6: 18.885 | C6: =IF('MRR Conglomerado'!AH6>0,'MRR Conglomerado'!AH6,"") | D6: =IF(C6="","",'MRR Conglomerado'!AT6) | E6: =IF(C6="","",D6/C6) | F6: =IF(C6="","",C6/B6) | G6: =IF(F6="","",IF(F6<100,"Menos de 100 USD",IF(F6<500,"100 a 500 USD",IF(F6<2000,"500 a 2.000 USD","Más de 2.000 USD")))) | H6: =IF(C6="","",MIN(D6,C6))
A7: AAG160805FE | B7: 18.885 | C7: =IF('MRR Conglomerado'!AH7>0,'MRR Conglomerado'!AH7,"") -> 2844.6476 | D7: =IF(C7="","",'MRR Conglomerado'!AT7) -> 2458.2747 | E7: =IF(C7="","",D7/C7) -> 0.86417551 | F7: =IF(C7="","",C7/B7) -> 150.63 | G7: =IF(F7="","",IF(F7<100,"Menos de 100 USD",IF(F7<500,"100 a 500 USD",IF(F7<2000,"500 a 2.000 USD","Más de 2.000 USD")))) -> 100 a 500 USD | H7: =IF(C7="","",MIN(D7,C7)) -> 2458.2747
A8: AAGA570212I | B8: 18.885 | C8: =IF('MRR Conglomerado'!AH8>0,'MRR Conglomerado'!AH8,"") -> 562.773 | D8: =IF(C8="","",'MRR Conglomerado'!AT8) -> 0 | E8: =IF(C8="","",D8/C8) -> 0 | F8: =IF(C8="","",C8/B8) -> 29.8 | G8: =IF(F8="","",IF(F8<100,"Menos de 100 USD",IF(F8<500,"100 a 500 USD",IF(F8<2000,"500 a 2.000 USD","Más de 2.000 USD")))) -> Menos de 100 USD | H8: =IF(C8="","",MIN(D8,C8)) -> 0
A9: AAM970602V7 | B9: 18.885 | C9: =IF('MRR Conglomerado'!AH9>0,'MRR Conglomerado'!AH9,"") | D9: =IF(C9="","",'MRR Conglomerado'!AT9) | E9: =IF(C9="","",D9/C9) | F9: =IF(C9="","",C9/B9) | G9: =IF(F9="","",IF(F9<100,"Menos de 100 USD",IF(F9<500,"100 a 500 USD",IF(F9<2000,"500 a 2.000 USD","Más de 2.000 USD")))) | H9: =IF(C9="","",MIN(D9,C9))
A10: AAR160311AL | B10: 18.885 | C10: =IF('MRR Conglomerado'!AH10>0,'MRR Conglomerado'!AH10,"") -> 6850.5337 | D10: =IF(C10="","",'MRR Conglomerado'!AT10) -> 7177.0561 | E10: =IF(C10="","",D10/C10) -> 1.0476638 | F10: =IF(C10="","",C10/B10) -> 362.75 | G10: =IF(F10="","",IF(F10<100,"Menos de 100 USD",IF(F10<500,"100 a 500 USD",IF(F10<2000,"500 a 2.000 USD","Más de 2.000 USD")))) -> 100 a 500 USD | H10: =IF(C10="","",MIN(D10,C10)) -> 6850.5337
A11: AARG6801036 | B11: 18.885 | C11: =IF('MRR Conglomerado'!AH11>0,'MRR Conglomerado'!AH11,"") | D11: =IF(C11="","",'MRR Conglomerado'!AT11) | E11: =IF(C11="","",D11/C11) | F11: =IF(C11="","",C11/B11) | G11: =IF(F11="","",IF(F11<100,"Menos de 100 USD",IF(F11<500,"100 a 500 USD",IF(F11<2000,"500 a 2.000 USD","Más de 2.000 USD")))) | H11: =IF(C11="","",MIN(D11,C11))
A12: AARG680103H | B12: 18.885 | C12: =IF('MRR Conglomerado'!AH12>0,'MRR Conglomerado'!AH12,"") | D12: =IF(C12="","",'MRR Conglomerado'!AT12) | E12: =IF(C12="","",D12/C12) | F12: =IF(C12="","",C12/B12) | G12: =IF(F12="","",IF(F12<100,"Menos de 100 USD",IF(F12<500,"100 a 500 USD",IF(F12<2000,"500 a 2.000 USD","Más de 2.000 USD")))) | H12: =IF(C12="","",MIN(D12,C12))
A13: AAS9610021I | B13: 18.885 | C13: =IF('MRR Conglomerado'!AH13>0,'MRR Conglomerado'!AH13,"") | D13: =IF(C13="","",'MRR Conglomerado'!AT13) | E13: =IF(C13="","",D13/C13) | F13: =IF(C13="","",C13/B13) | G13: =IF(F13="","",IF(F13<100,"Menos de 100 USD",IF(F13<500,"100 a 500 USD",IF(F13<2000,"500 a 2.000 USD","Más de 2.000 USD")))) | H13: =IF(C13="","",MIN(D13,C13))
... A784: ZSU920314FC | B784: 18.885 | C784: =IF('MRR Conglomerado'!AH784>0,'MRR Conglomerado'!AH784,"") -> 7199.9062 | D784: =IF(C784="","",'MRR Conglomerado'!AT784) -> 0 | E784: =IF(C784="","",D784/C784) -> 0 | F784: =IF(C784="","",C784/B784) -> 381.25 | G784: =IF(F784="","",IF(F784<100,"Menos de 100 USD",IF(F784<500,"100 a 500 USD",IF(F784<2000,"500 a 2.000 USD","Más de 2.000 USD")))) -> 100 a 500 USD | H784: =IF(C784="","",MIN(D784,C784)) -> 0

Sheet Detalle Fuga 2026-06
A1: Conglomerado | B1: Empresa(s) | C1: MRR jun-2025 MXN (perdido) | D1: Tamaño USD | E1: Segmento | F1: Último mes con MRR | G1: Meses con MRR (vida) | H1: MRR jun-2026 (verificación) | J1: TC MXN/USD jun-25: | K1: 18.885
A2: ='MRR Conglomerado'!A61 -> ATE100413UD | B2: ='MRR Conglomerado'!B61 -> ALIADOS EN TECNOLOGIA | C2: ='MRR Conglomerado'!AH61 -> 25999.924 | D2: =C2/$K$1 -> 1376.75 | E2: =IF(D2<100,"Menos de 100 USD",IF(D2<500,"100 a 500 USD",IF(D2<2000,"500 a 2.000 USD","Más de 2.000 USD"))) -> 500 a 2.000 USD | F2: =LOOKUP(2,1/('MRR Conglomerado'!E61:AT61>0),'MRR Conglomerado'!$E$1:$AT$1) -> 2025-09 | G2: =COUNTIF('MRR Conglomerado'!E61:AT61,">0") -> 4 | H2: ='MRR Conglomerado'!AT61 -> 0
A3: ='MRR Conglomerado'!A238 -> EHM910503BW | B3: ='MRR Conglomerado'!B238 -> EQUIPOS HIDROMECANICOS MC | C3: ='MRR Conglomerado'!AH238 -> 15678.516 | D3: =C3/$K$1 -> 830.21 | E3: =IF(D3<100,"Menos de 100 USD",IF(D3<500,"100 a 500 USD",IF(D3<2000,"500 a 2.000 USD","Más de 2.000 USD"))) -> 500 a 2.000 USD | F3: =LOOKUP(2,1/('MRR Conglomerado'!E238:AT238>0),'MRR Conglomerado'!$E$1:$AT$1) -> 2025-11 | G3: =COUNTIF('MRR Conglomerado'!E238:AT238,">0") -> 35 | H3: ='MRR Conglomerado'!AT238 -> 0
A4: ='MRR Conglomerado'!A497 -> MSP981215H4 | B4: ='MRR Conglomerado'!B497 -> MERCURIO SEGURIDAD PRIVADA | C4: ='MRR Conglomerado'!AH497 -> 15361.437 | D4: =C4/$K$1 -> 813.42 | E4: =IF(D4<100,"Menos de 100 USD",IF(D4<500,"100 a 500 USD",IF(D4<2000,"500 a 2.000 USD","Más de 2.000 USD"))) -> 500 a 2.000 USD | F4: =LOOKUP(2,1/('MRR Conglomerado'!E497:AT497>0),'MRR Conglomerado'!$E$1:$AT$1) -> 2025-10 | G4: =COUNTIF('MRR Conglomerado'!E497:AT497,">0") -> 8 | H4: ='MRR Conglomerado'!AT497 -> 0
A5: ='MRR Conglomerado'!A570 -> PLO2310139T | B5: ='MRR Conglomerado'!B570 -> PROXIMIDAD Y LOGISTICA | C5: ='MRR Conglomerado'!AH570 -> 15023.017 | D5: =C5/$K$1 -> 795.5 | E5: =IF(D5<100,"Menos de 100 USD",IF(D5<500,"100 a 500 USD",IF(D5<2000,"500 a 2.000 USD","Más de 2.000 USD"))) -> 500 a 2.000 USD | F5: =LOOKUP(2,1/('MRR Conglomerado'!E570:AT570>0),'MRR Conglomerado'!$E$1:$AT$1) -> 2025-10 | G5: =COUNTIF('MRR Conglomerado'!E570:AT570,">0") -> 22 | H5: ='MRR Conglomerado'!AT570 -> 0
A6: ='MRR Conglomerado'!A699 -> TAD140205H9 | B6: ='MRR Conglomerado'!B699 -> TIENDAS ADITIVO | C6: ='MRR Conglomerado'!AH699 -> 12297.723 | D6: =C6/$K$1 -> 651.19 | E6: =IF(D6<100,"Menos de 100 USD",IF(D6<500,"100 a 500 USD",IF(D6<2000,"500 a 2.000 USD","Más de 2.000 USD"))) -> 500 a 2.000 USD | F6: =LOOKUP(2,1/('MRR Conglomerado'!E699:AT699>0),'MRR Conglomerado'!$E$1:$AT$1) -> 2026-05 | G6: =COUNTIF('MRR Conglomerado'!E699:AT699,">0") -> 41 | H6: ='MRR Conglomerado'!AT699 -> 0
A7: ='MRR Conglomerado'!A311 -> GCA6601031M | B7: ='MRR Conglomerado'!B311 -> GRUPO COMERCIAL ATLAS | C7: ='MRR Conglomerado'!AH311 -> 11393.32 | D7: =C7/$K$1 -> 603.3 | E7: =IF(D7<100,"Menos de 100 USD",IF(D7<500,"100 a 500 USD",IF(D7<2000,"500 a 2.000 USD","Más de 2.000 USD"))) -> 500 a 2.000 USD | F7: =LOOKUP(2,1/('MRR Conglomerado'!E311:AT311>0),'MRR Conglomerado'!$E$1:$AT$1) -> 2025-10 | G7: =COUNTIF('MRR Conglomerado'!E311:AT311,">0") -> 34 | H7: ='MRR Conglomerado'!AT311 -> 0
A8: ='MRR Conglomerado'!A415 -> ITM100309S9 | B8: ='MRR Conglomerado'!B415 -> INSTALACIONES DE TELECOMUNICACIONES DE MEXICO | C8: ='MRR Conglomerado'!AH415 -> 11280.011 | D8: =C8/$K$1 -> 597.3 | E8: =IF(D8<100,"Menos de 100 USD",IF(D8<500,"100 a 500 USD",IF(D8<2000,"500 a 2.000 USD","Más de 2.000 USD"))) -> 500 a 2.000 USD | F8: =LOOKUP(2,1/('MRR Conglomerado'!E415:AT415>0),'MRR Conglomerado'!$E$1:$AT$1) -> 2025-10 | G8: =COUNTIF('MRR Conglomerado'!E415:AT415,">0") -> 6 | H8: ='MRR Conglomerado'!AT415 -> 0
A9: ='MRR Conglomerado'!A140 -> CIC991005MS | B9: ='MRR Conglomerado'!B140 -> CONSTRUCTORA E INMOBILIARIA CAROME | C9: ='MRR Conglomerado'!AH140 -> 9846.8278 | D9: =C9/$K$1 -> 521.41 | E9: =IF(D9<100,"Menos de 100 USD",IF(D9<500,"100 a 500 USD",IF(D9<2000,"500 a 2.000 USD","Más de 2.000 USD"))) -> 500 a 2.000 USD | F9: =LOOKUP(2,1/('MRR Conglomerado'!E140:AT140>0),'MRR Conglomerado'!$E$1:$AT$1) -> 2026-01 | G9: =COUNTIF('MRR Conglomerado'!E140:AT140,">0") -> 19 | H9: ='MRR Conglomerado'!AT140 -> 0
A10: ='MRR Conglomerado'!A317 -> GCP831026IG | B10: ='MRR Conglomerado'!B317 -> GRAN CAFE DE LA PARROQUIA DE VERACRUZ | C10: ='MRR Conglomerado'!AH317 -> 9460.0631 | D10: =C10/$K$1 -> 500.93 | E10: =IF(D10<100,"Menos de 100 USD",IF(D10<500,"100 a 500 USD",IF(D10<2000,"500 a 2.000 USD","Más de 2.000 USD"))) -> 500 a 2.000 USD | F10: =LOOKUP(2,1/('MRR Conglomerado'!E317:AT317>0),'MRR Conglomerado'!$E$1:$AT$1) -> 2025-07 | G10: =COUNTIF('MRR Conglomerado'!E317:AT317,">0") -> 12 | H10: ='MRR Conglomerado'!AT317 -> 0
A11: ='MRR Conglomerado'!A563 -> PIM88041917 | B11: ='MRR Conglomerado'!B563 -> PLASTICOS INDUSTRIALES DE MONTERREY | C11: ='MRR Conglomerado'!AH563 -> 9192.0849 | D11: =C11/$K$1 -> 486.74 | E11: =IF(D11<100,"Menos de 100 USD",IF(D11<500,"100 a 500 USD",IF(D11<2000,"500 a 2.000 USD","Más de 2.000 USD"))) -> 100 a 500 USD | F11: =LOOKUP(2,1/('MRR Conglomerado'!E563:AT563>0),'MRR Conglomerado'!$E$1:$AT$1) -> 2026-05 | G11: =COUNTIF('MRR Conglomerado'!E563:AT563,">0") -> 29 | H11: ='MRR Conglomerado'!AT563 -> 0
A12: ='MRR Conglomerado'!A761 -> VJU981123KB | B12: ='MRR Conglomerado'!B761 -> VILLAGOMEZ JURADO | C12: ='MRR Conglomerado'!AH761 -> 9108.0467 | D12: =C12/$K$1 -> 482.29 | E12: =IF(D12<100,"Menos de 100 USD",IF(D12<500,"100 a 500 USD",IF(D12<2000,"500 a 2.000 USD","Más de 2.000 USD"))) -> 100 a 500 USD | F12: =LOOKUP(2,1/('MRR Conglomerado'!E761:AT761>0),'MRR Conglomerado'!$E$1:$AT$1) -> 2026-04 | G12: =COUNTIF('MRR Conglomerado'!E761:AT761,">0") -> 36 | H12: ='MRR Conglomerado'!AT761 -> 0
A13: ='MRR Conglomerado'!A630 -> RTD220308U2 | B13: ='MRR Conglomerado'!B630 -> RM TEAM 2022 | C13: ='MRR Conglomerado'!AH630 -> 8693.1432 | D13: =C13/$K$1 -> 460.32 | E13: =IF(D13<100,"Menos de 100 USD",IF(D13<500,"100 a 500 USD",IF(D13<2000,"500 a 2.000 USD","Más de 2.000 USD"))) -> 100 a 500 USD | F13: =LOOKUP(2,1/('MRR Conglomerado'!E630:AT630>0),'MRR Conglomerado'!$E$1:$AT$1) -> 2025-08 | G13: =COUNTIF('MRR Conglomerado'!E630:AT630,">0") -> 32 | H13: ='MRR Conglomerado'!AT630 -> 0
A14: ='MRR Conglomerado'!A682 -> SNO0202153Z | B14: ='MRR Conglomerado'!B682 -> SIMILARES DEL NORESTE | C14: ='MRR Conglomerado'!AH682 -> 8449.7156 | D14: =C14/$K$1 -> 447.43 | E14: =IF(D14<100,"Menos de 100 USD",IF(D14<500,"100 a 500 USD",IF(D14<2000,"500 a 2.000 USD","Más de 2.000 USD"))) -> 100 a 500 USD | F14: =LOOKUP(2,1/('MRR Conglomerado'!E682:AT682>0),'MRR Conglomerado'!$E$1:$AT$1) -> 2025-10 | G14: =COUNTIF('MRR Conglomerado'!E682:AT682,">0") -> 12 | H14: ='MRR Conglomerado'!AT682 -> 0
A15: ='MRR Conglomerado'!A572 -> PLT7910247B | B15: ='MRR Conglomerado'!B572 -> PRODUCTOS LOL TUN | C15: ='MRR Conglomerado'!AH572 -> 8161.7193 | D15: =C15/$K$1 -> 432.18 | E15: =IF(D15<100,"Menos de 100 USD",IF(D15<500,"100 a 500 USD",IF(D15<2000,"500 a 2.000 USD","Más de 2.000 USD"))) -> 100 a 500 USD | F15: =LOOKUP(2,1/('MRR Conglomerado'!E572:AT572>0),'MRR Conglomerado'!$E$1:$AT$1) -> 2025-12 | G15: =COUNTIF('MRR Conglomerado'!E572:AT572,">0") -> 36 | H15: ='MRR Conglomerado'!AT572 -> 0
A16: ='MRR Conglomerado'!A43 -> ALO0508239T | B16: ='MRR Conglomerado'!B43 -> ABC LOGISTICA | C16: ='MRR Conglomerado'!AH43 -> 7337.0113 | D16: =C16/$K$1 -> 388.51 | E16: =IF(D16<100,"Menos de 100 USD",IF(D16<500,"100 a 500 USD",IF(D16<2000,"500 a 2.000 USD","Más de 2.000 USD"))) -> 100 a 500 USD | F16: =LOOKUP(2,1/('MRR Conglomerado'!E43:AT43>0),'MRR Conglomerado'!$E$1:$AT$1) -> 2025-06 | G16: =COUNTIF('MRR Conglomerado'!E43:AT43,">0") -> 8 | H16: ='MRR Conglomerado'!AT43 -> 0
A17: ='MRR Conglomerado'!A784 -> ZSU920314FC | B17: ='MRR Conglomerado'!B784 -> ZAPATERIAS SUPER | C17: ='MRR Conglomerado'!AH784 -> 7199.9062 | D17: =C17/$K$1 -> 381.25 | E17: =IF(D17<100,"Menos de 100 USD",IF(D17<500,"100 a 500 USD",IF(D17<2000,"500 a 2.000 USD","Más de 2.000 USD"))) -> 100 a 500 USD | F17: =LOOKUP(2,1/('MRR Conglomerado'!E784:AT784>0),'MRR Conglomerado'!$E$1:$AT$1) -> 2026-02 | G17: =COUNTIF('MRR Conglomerado'!E784:AT784,">0") -> 20 | H17: ='MRR Conglomerado'!AT784 -> 0
A18: ='MRR Conglomerado'!A72 -> BAN191001Q6 | B18: ='MRR Conglomerado'!B72 -> BKAYA | C18: ='MRR Conglomerado'!AH72 -> 7091.3175 | D18: =C18/$K$1 -> 375.5 | E18: =IF(D18<100,"Menos de 100 USD",IF(D18<500,"100 a 500 USD",IF(D18<2000,"500 a 2.000 USD","Más de 2.000 USD"))) -> 100 a 500 USD | F18: =LOOKUP(2,1/('MRR Conglomerado'!E72:AT72>0),'MRR Conglomerado'!$E$1:$AT$1) -> 2026-04 | G18: =COUNTIF('MRR Conglomerado'!E72:AT72,">0") -> 36 | H18: ='MRR Conglomerado'!AT72 -> 0
A19: ='MRR Conglomerado'!A490 -> MRC210607EW | B19: ='MRR Conglomerado'!B490 -> MEDICA RISO CDMX | C19: ='MRR Conglomerado'!AH490 -> 6815.7854 | D19: =C19/$K$1 -> 360.91 | E19: =IF(D19<100,"Menos de 100 USD",IF(D19<500,"100 a 500 USD",IF(D19<2000,"500 a 2.000 USD","Más de 2.000 USD"))) -> 100 a 500 USD | F19: =LOOKUP(2,1/('MRR Conglomerado'!E490:AT490>0),'MRR Conglomerado'!$E$1:$AT$1) -> 2025-08 | G19: =COUNTIF('MRR Conglomerado'!E490:AT490,">0") -> 13 | H19: ='MRR Conglomerado'!AT490 -> 0
A20: ='MRR Conglomerado'!A111 -> CCL8603057Q | B20: ='MRR Conglomerado'!B111 -> CONFECCIONES CLABECK | C20: ='MRR Conglomerado'!AH111 -> 6196.5462 | D20: =C20/$K$1 -> 328.12 | E20: =IF(D20<100,"Menos de 100 USD",IF(D20<500,"100 a 500 USD",IF(D20<2000,"500 a 2.000 USD","Más de 2.000 USD"))) -> 100 a 500 USD | F20: =LOOKUP(2,1/('MRR Conglomerado'!E111:AT111>0),'MRR Conglomerado'!$E$1:$AT$1) -> 2025-08 | G20: =COUNTIF('MRR Conglomerado'!E111:AT111,">0") -> 12 | H20: ='MRR Conglomerado'!AT111 -> 0
A21: ='MRR Conglomerado'!A324 -> GED62010165 | B21: ='MRR Conglomerado'!B324 -> GOBIERNO DEL ESTADO DE DURANGO | C21: ='MRR Conglomerado'!AH324 -> 5876.6343 | D21: =C21/$K$1 -> 311.18 | E21: =IF(D21<100,"Menos de 100 USD",IF(D21<500,"100 a 500 USD",IF(D21<2000,"500 a 2.000 USD","Más de 2.000 USD"))) -> 100 a 500 USD | F21: =LOOKUP(2,1/('MRR Conglomerado'!E324:AT324>0),'MRR Conglomerado'!$E$1:$AT$1) -> 2026-03 | G21: =COUNTIF('MRR Conglomerado'!E324:AT324,">0") -> 34 | H21: ='MRR Conglomerado'!AT324 -> 0
A22: ='MRR Conglomerado'!A207 -> DMA150609DQ | B22: ='MRR Conglomerado'!B207 -> DESARROLLOS MAFERSA | C22: ='MRR Conglomerado'!AH207 -> 5856.0496 | D22: =C22/$K$1 -> 310.09 | E22: =IF(D22<100,"Menos de 100 USD",IF(D22<500,"100 a 500 USD",IF(D22<2000,"500 a 2.000 USD","Más de 2.000 USD"))) -> 100 a 500 USD | F22: =LOOKUP(2,1/('MRR Conglomerado'!E207:AT207>0),'MRR Conglomerado'!$E$1:$AT$1) -> 2025-11 | G22: =COUNTIF('MRR Conglomerado'!E207:AT207,">0") -> 6 | H22: ='MRR Conglomerado'!AT207 -> 0
A23: ='MRR Conglomerado'!A669 -> SIP050722BA | B23: ='MRR Conglomerado'!B669 -> SUMINISTROS INTEGRALES PANAMERICANOS | C23: ='MRR Conglomerado'!AH669 -> 5789.9522 | D23: =C23/$K$1 -> 306.59 | E23: =IF(D23<100,"Menos de 100 USD",IF(D23<500,"100 a 500 USD",IF(D23<2000,"500 a 2.000 USD","Más de 2.000 USD"))) -> 100 a 500 USD | F23: =LOOKUP(2,1/('MRR Conglomerado'!E669:AT669>0),'MRR Conglomerado'!$E$1:$AT$1) -> 2025-09 | G23: =COUNTIF('MRR Conglomerado'!E669:AT669,">0") -> 14 | H23: ='MRR Conglomerado'!AT669 -> 0
A24: ='MRR Conglomerado'!A750 -> VAPR870821D | B24: ='MRR Conglomerado'!B750 -> RODOLFO VALTIERRA PICOS | C24: ='MRR Conglomerado'!AH750 -> 5619.6094 | D24: =C24/$K$1 -> 297.57 | E24: =IF(D24<100,"Menos de 100 USD",IF(D24<500,"100 a 500 USD",IF(D24<2000,"500 a 2.000 USD","Más de 2.000 USD"))) -> 100 a 500 USD | F24: =LOOKUP(2,1/('MRR Conglomerado'!E750:AT750>0),'MRR Conglomerado'!$E$1:$AT$1) -> 2025-12 | G24: =COUNTIF('MRR Conglomerado'!E750:AT750,">0") -> 36 | H24: ='MRR Conglomerado'!AT750 -> 0
A25: ='MRR Conglomerado'!A517 -> OGA101029LS | B25: ='MRR Conglomerado'!B517 -> OPERADORA DE GRANOS Y ALMACENES | C25: ='MRR Conglomerado'!AH517 -> 5451.9106 | D25: =C25/$K$1 -> 288.69 | E25: =IF(D25<100,"Menos de 100 USD",IF(D25<500,"100 a 500 USD",IF(D25<2000,"500 a 2.000 USD","Más de 2.000 USD"))) -> 100 a 500 USD | F25: =LOOKUP(2,1/('MRR Conglomerado'!E517:AT517>0),'MRR Conglomerado'!$E$1:$AT$1) -> 2026-02 | G25: =COUNTIF('MRR Conglomerado'!E517:AT517,">0") -> 23 | H25: ='MRR Conglomerado'!AT517 -> 0
A26: ='MRR Conglomerado'!A634 -> SAC18120569 | B26: ='MRR Conglomerado'!B634 -> SERVICIOS DE AUTOTRANSPORTE CAZAMA | C26: ='MRR Conglomerado'!AH634 -> 5395.0668 | D26: =C26/$K$1 -> 285.68 | E26: =IF(D26<100,"Menos de 100 USD",IF(D26<500,"100 a 500 USD",IF(D26<2000,"500 a 2.000 USD","Más de 2.000 USD"))) -> 100 a 500 USD | F26: =LOOKUP(2,1/('MRR Conglomerado'!E634:AT634>0),'MRR Conglomerado'!$E$1:$AT$1) -> 2026-01 | G26: =COUNTIF('MRR Conglomerado'!E634:AT634,">0") -> 13 | H26: ='MRR Conglomerado'!AT634 -> 0
A27: ='MRR Conglomerado'!A382 -> HUC21101387 | B27: ='MRR Conglomerado'!B382 -> HAICO URBANIZACION Y CONSTRUCCION | C27: ='MRR Conglomerado'!AH382 -> 5361.6403 | D27: =C27/$K$1 -> 283.91 | E27: =IF(D27<100,"Menos de 100 USD",IF(D27<500,"100 a 500 USD",IF(D27<2000,"500 a 2.000 USD","Más de 2.000 USD"))) -> 100 a 500 USD | F27: =LOOKUP(2,1/('MRR Conglomerado'!E382:AT382>0),'MRR Conglomerado'!$E$1:$AT$1) -> 2025-11 | G27: =COUNTIF('MRR Conglomerado'!E382:AT382,">0") -> 28 | H27: ='MRR Conglomerado'!AT382 -> 0
A28: ='MRR Conglomerado'!A262 -> ETP2208223L | B28: ='MRR Conglomerado'!B262 -> ESQUEMAS TACTICOS DE PROMOCION | C28: ='MRR Conglomerado'!AH262 -> 4200.024 | D28: =C28/$K$1 -> 222.4 | E28: =IF(D28<100,"Menos de 100 USD",IF(D28<500,"100 a 500 USD",IF(D28<2000,"500 a 2.000 USD","Más de 2.000 USD"))) -> 100 a 500 USD | F28: =LOOKUP(2,1/('MRR Conglomerado'!E262:AT262>0),'MRR Conglomerado'!$E$1:$AT$1) -> 2025-07 | G28: =COUNTIF('MRR Conglomerado'!E262:AT262,">0") -> 6 | H28: ='MRR Conglomerado'!AT262 -> 0
A29: ='MRR Conglomerado'!A250 -> ENE150506UG | B29: ='MRR Conglomerado'!B250 -> ENESTAS | C29: ='MRR Conglomerado'!AH250 -> 4192.47 | D29: =C29/$K$1 -> 222 | E29: =IF(D29<100,"Menos de 100 USD",IF(D29<500,"100 a 500 USD",IF(D29<2000,"500 a 2.000 USD","Más de 2.000 USD"))) -> 100 a 500 USD | F29: =LOOKUP(2,1/('MRR Conglomerado'!E250:AT250>0),'MRR Conglomerado'!$E$1:$AT$1) -> 2026-01 | G29: =COUNTIF('MRR Conglomerado'!E250:AT250,">0") -> 13 | H29: ='MRR Conglomerado'!AT250 -> 0
A30: ='MRR Conglomerado'!A310 -> GCA100623EZ | B30: ='MRR Conglomerado'!B310 -> GRUPO CONSTRUCTOR AQUILES | C30: ='MRR Conglomerado'!AH310 -> 4149.9788 | D30: =C30/$K$1 -> 219.75 | E30: =IF(D30<100,"Menos de 100 USD",IF(D30<500,"100 a 500 USD",IF(D30<2000,"500 a 2.000 USD","Más de 2.000 USD"))) -> 100 a 500 USD | F30: =LOOKUP(2,1/('MRR Conglomerado'!E310:AT310>0),'MRR Conglomerado'!$E$1:$AT$1) -> 2025-10 | G30: =COUNTIF('MRR Conglomerado'!E310:AT310,">0") -> 5 | H30: ='MRR Conglomerado'!AT310 -> 0
A31: ='MRR Conglomerado'!A742 -> UCO040903MP | B31: ='MRR Conglomerado'!B742 -> UNIQUE COMM | C31: ='MRR Conglomerado'!AH742 -> 3875.9574 | D31: =C31/$K$1 -> 205.24 | E31: =IF(D31<100,"Menos de 100 USD",IF(D31<500,"100 a 500 USD",IF(D31<2000,"500 a 2.000 USD","Más de 2.000 USD"))) -> 100 a 500 USD | F31: =LOOKUP(2,1/('MRR Conglomerado'!E742:AT742>0),'MRR Conglomerado'!$E$1:$AT$1) -> 2026-01 | G31: =COUNTIF('MRR Conglomerado'!E742:AT742,">0") -> 14 | H31: ='MRR Conglomerado'!AT742 -> 0
A32: ='MRR Conglomerado'!A349 -> GNE21082028 | B32: ='MRR Conglomerado'!B349 -> GRUPO NEEF | C32: ='MRR Conglomerado'!AH349 -> 3560.0114 | D32: =C32/$K$1 -> 188.51 | E32: =IF(D32<100,"Menos de 100 USD",IF(D32<500,"100 a 500 USD",IF(D32<2000,"500 a 2.000 USD","Más de 2.000 USD"))) -> 100 a 500 USD | F32: =LOOKUP(2,1/('MRR Conglomerado'!E349:AT349>0),'MRR Conglomerado'!$E$1:$AT$1) -> 2025-07 | G32: =COUNTIF('MRR Conglomerado'!E349:AT349,">0") -> 6 | H32: ='MRR Conglomerado'!AT349 -> 0
A33: ='MRR Conglomerado'!A450 -> LSM020731CZ | B33: ='MRR Conglomerado'!B450 -> LEE SPRING DE MEXICO | C33: ='MRR Conglomerado'!AH450 -> 3554.9124 | D33: =C33/$K$1 -> 188.24 | E33: =IF(D33<100,"Menos de 100 USD",IF(D33<500,"100 a 500 USD",IF(D33<2000,"500 a 2.000 USD","Más de 2.000 USD"))) -> 100 a 500 USD | F33: =LOOKUP(2,1/('MRR Conglomerado'!E450:AT450>0),'MRR Conglomerado'!$E$1:$AT$1) -> 2025-06 | G33: =COUNTIF('MRR Conglomerado'!E450:AT450,">0") -> 5 | H33: ='MRR Conglomerado'!AT450 -> 0
A34: ='MRR Conglomerado'!A545 -> PBA191125B3 | B34: ='MRR Conglomerado'!B545 -> PALMERA BONITA ACAPULCO | C34: ='MRR Conglomerado'!AH545 -> 3516.7647 | D34: =C34/$K$1 -> 186.22 | E34: =IF(D34<100,"Menos de 100 USD",IF(D34<500,"100 a 500 USD",IF(D34<2000,"500 a 2.000 USD","Más de 2.000 USD"))) -> 100 a 500 USD | F34: =LOOKUP(2,1/('MRR Conglomerado'!E545:AT545>0),'MRR Conglomerado'!$E$1:$AT$1) -> 2025-09 | G34: =COUNTIF('MRR Conglomerado'!E545:AT545,">0") -> 17 | H34: ='MRR Conglomerado'!AT545 -> 0
A35: ='MRR Conglomerado'!A29 -> AEAR791019G | B35: ='MRR Conglomerado'!B29 -> RONALD ARELLANO ARELLANO | C35: ='MRR Conglomerado'!AH29 -> 3180.0451 | D35: =C35/$K$1 -> 168.39 | E35: =IF(D35<100,"Menos de 100 USD",IF(D35<500,"100 a 500 USD",IF(D35<2000,"500 a 2.000 USD","Más de 2.000 USD"))) -> 100 a 500 USD | F35: =LOOKUP(2,1/('MRR Conglomerado'!E29:AT29>0),'MRR Conglomerado'!$E$1:$AT$1) -> 2025-08 | G35: =COUNTIF('MRR Conglomerado'!E29:AT29,">0") -> 3 | H35: ='MRR Conglomerado'!AT29 -> 0
A36: ='MRR Conglomerado'!A264 -> EVN190625UL | B36: ='MRR Conglomerado'!B264 -> ENERGIA VERDE Y NEGOCIOS SUSTENTABLES | C36: ='MRR Conglomerado'!AH264 -> 2844.081 | D36: =C36/$K$1 -> 150.6 | E36: =IF(D36<100,"Menos de 100 USD",IF(D36<500,"100 a 500 USD",IF(D36<2000,"500 a 2.000 USD","Más de 2.000 USD"))) -> 100 a 500 USD | F36: =LOOKUP(2,1/('MRR Conglomerado'!E264:AT264>0),'MRR Conglomerado'!$E$1:$AT$1) -> 2026-05 | G36: =COUNTIF('MRR Conglomerado'!E264:AT264,">0") -> 19 | H36: ='MRR Conglomerado'!AT264 -> 0
A37: ='MRR Conglomerado'!A180 -> CTE1804309D | B37: ='MRR Conglomerado'!B180 -> CARIBE TAXI EXPRESS | C37: ='MRR Conglomerado'!AH180 -> 2699.9884 | D37: =C37/$K$1 -> 142.97 | E37: =IF(D37<100,"Menos de 100 USD",IF(D37<500,"100 a 500 USD",IF(D37<2000,"500 a 2.000 USD","Más de 2.000 USD"))) -> 100 a 500 USD | F37: =LOOKUP(2,1/('MRR Conglomerado'!E180:AT180>0),'MRR Conglomerado'!$E$1:$AT$1) -> 2026-01 | G37: =COUNTIF('MRR Conglomerado'!E180:AT180,">0") -> 8 | H37: ='MRR Conglomerado'!AT180 -> 0
A38: ='MRR Conglomerado'!A654 -> SEI240528FF | B38: ='MRR Conglomerado'!B654 -> SOLUCIONES EMPRESARIALES INTEGRALES LIZAMA | C38: ='MRR Conglomerado'!AH654 -> 2625.015 | D38: =C38/$K$1 -> 139 | E38: =IF(D38<100,"Menos de 100 USD",IF(D38<500,"100 a 500 USD",IF(D38<2000,"500 a 2.000 USD","Más de 2.000 USD"))) -> 100 a 500 USD | F38: =LOOKUP(2,1/('MRR Conglomerado'!E654:AT654>0),'MRR Conglomerado'!$E$1:$AT$1) -> 2025-06 | G38: =COUNTIF('MRR Conglomerado'!E654:AT654,">0") -> 3 | H38: ='MRR Conglomerado'!AT654 -> 0
A39: ='MRR Conglomerado'!A694 -> STI070725SA | B39: ='MRR Conglomerado'!B694 -> SOLUCIONES PARA TI | C39: ='MRR Conglomerado'!AH694 -> 2448.2514 | D39: =C39/$K$1 -> 129.64 | E39: =IF(D39<100,"Menos de 100 USD",IF(D39<500,"100 a 500 USD",IF(D39<2000,"500 a 2.000 USD","Más de 2.000 USD"))) -> 100 a 500 USD | F39: =LOOKUP(2,1/('MRR Conglomerado'!E694:AT694>0),'MRR Conglomerado'!$E$1:$AT$1) -> 2025-12 | G39: =COUNTIF('MRR Conglomerado'!E694:AT694,">0") -> 23 | H39: ='MRR Conglomerado'!AT694 -> 0
A40: ='MRR Conglomerado'!A679 -> SMM090918UU | B40: ='MRR Conglomerado'!B679 -> SERVICIOS MEDICOS MAGAMED | C40: ='MRR Conglomerado'!AH679 -> 2083.9597 | D40: =C40/$K$1 -> 110.35 | E40: =IF(D40<100,"Menos de 100 USD",IF(D40<500,"100 a 500 USD",IF(D40<2000,"500 a 2.000 USD","Más de 2.000 USD"))) -> 100 a 500 USD | F40: =LOOKUP(2,1/('MRR Conglomerado'!E679:AT679>0),'MRR Conglomerado'!$E$1:$AT$1) -> 2025-06 | G40: =COUNTIF('MRR Conglomerado'!E679:AT679,">0") -> 15 | H40: ='MRR Conglomerado'!AT679 -> 0
...

Sheet Notas
A1: NOTAS — MÉXICO, NRR DE JUNIO 2026, BASE MENSUAL, POR SEGMENTO DE TAMAÑO
A3: Definición: NRR del mes X = MRR de la cohorte en X / MRR en X-12, con cohorte = conglomerados de México con
A4: MRR > 0 en X-12 (se omiten los creados desde el mes siguiente). Todo el cálculo en MXN (moneda local = tipo de
A5: cambio original). USD sólo para segmentar por tamaño: MRR del mes base ÷ TC MXN/USD del mes base (hoja TC del
A6: archivo original): jun-25: 18,885 (ver celda B del detalle).
A7: Segmentos: < 100; 100 a 499,99; 500 a 1.999,99; 2.000 o más USD.
A9: Hoja "MRR Conglomerado": MRR mensual MXN por conglomerado (suma de sus RUT en México), extraído de
A10: "MRR Consolidado Moneda Loca v2" con trazabilidad en la columna C. Únicos valores pegados; el resto son fórmulas.
A11: Hoja "Detalle 2026-06": base (jun-25), actual (jun-26), NRR, tamaño USD, segmento y MRR retenido por conglomerado.
A12: Hoja "Resumen": N, fuga, % fuga, GRR y NRR por segmento y total, con fórmulas SUMIFS/COUNTIFS sobre los detalles.
A14: Advertencia: el segmento "Más de 2.000 USD" en México tiene ~5 cuentas; su NRR es muy sensible a una sola cuenta.
A16: Hoja "Detalle Fuga 2026-06": las 86 cuentas de la cohorte que quedaron en MRR = 0 en jun-2026, con su MRR perdido,
A17: tamaño, segmento, último mes con MRR y meses de vida. La fuga suma 323.985 MXN (~17.156 USD) = 15,6% del MRR base de la cohorte.
